Workbook

Sheet 条件
A1: 日中（9:00〜18:00）の室外機の稼働時間
A2: 運転の判定（tools/operation_judge.py と同じ。push済みの「稼働状況の判定」と1時間ごとの判定が一致することを確認済み）
A3: ① 1分ごと：排気温度 − 吸気温度（3方位の平均）の10分移動中央値が1.0℃以上なら「運転中」
A4: ② 1時間ごと：判定できた分が48分以上あり、そのうち80％以上が運転中なら「運転」（断続・停止・判定不能は数えない）
A5: ③ 日ごと：9〜17時台の9時間のうち「運転」の時間を数える。判定できた時間が7時間未満の日は空欄
A6: ④ 列の値：3台の平均（その日に値がある室外機だけで平均）
A7: ⑤ 研究に使える時間：平日に、組（芋緑化ありの室外機と同じ区画の列3）の2台がともに「運転」の時間。土日祝は空欄
A8: 空欄の主な理由：8-2の排気温度の欠測（8/14〜8/28）、3-2の排気温度の欠測（8/30〜9/7、9/14〜9/22ごろ）、列11のデータなし（9/15〜10/1）、7/29（設置当日）、10/13（14時ごろで記録終了）
A9: 値はPythonで1分値から計算した。期間別のまとめは数式で集計している

Sheet 日ごとの稼働時間
A1: 日ごとの稼働時間［時間］（9〜17時台の9時間のうち「運転」の時間）
A2: 灰色の行は土日祝。列3・列8・列11は3台の平均
A3: 日付 | B3: 表示用 | C3: 曜日 | D3: 区分 | E3: 3-1 | F3: 3-2 | G3: 3-3 | H3: 8-1 | I3: 8-2 | J3: 8-3 | K3: 11-1 | L3: 11-2 | M3: 11-3 | N3: 列3 | O3: 列8 | P3: 列11 | Q3: 土日祝（グラフの帯）
A4: 46232 | B4: 7/29 | C4: 水 | D4: 平日
A5: 46233 | B5: 7/30 | C5: 木 | D5: 平日 | E5: 9 | F5: 9 | G5: 9 | H5: 8 | I5: 9 | J5: 8 | K5: 8 | L5: 8 | M5: 8 | N5: 9 | O5: 8.33 | P5: 8
A6: 46234 | B6: 7/31 | C6: 金 | D6: 平日 | E6: 9 | F6: 9 | G6: 9 | H6: 6 | I6: 8 | J6: 8 | K6: 6 | L6: 8 | M6: 9 | N6: 9 | O6: 7.33 | P6: 7.67
A7: 46235 | B7: 8/1 | C7: 土 | D7: 土日 | E7: 9 | F7: 9 | G7: 9 | H7: 5 | I7: 5 | J7: 4 | K7: 7 | L7: 6 | M7: 9 | N7: 9 | O7: 4.67 | P7: 7.33 | Q7: 9
A8: 46236 | B8: 8/2 | C8: 日 | D8: 土日 | E8: 9 | F8: 9 | G8: 9 | H8: 9 | I8: 2 | J8: 0 | K8: 7 | L8: 5 | M8: 8 | N8: 9 | O8: 3.67 | P8: 6.67 | Q8: 9
A9: 46237 | B9: 8/3 | C9: 月 | D9: 平日 | E9: 9 | F9: 9 | G9: 9 | H9: 7 | I9: 9 | J9: 8 | K9: 5 | L9: 9 | M9: 7 | N9: 9 | O9: 8 | P9: 7
A10: 46238 | B10: 8/4 | C10: 火 | D10: 平日 | E10: 8 | F10: 8 | G10: 9 | H10: 6 | I10: 9 | J10: 6 | K10: 5 | L10: 7 | M10: 7 | N10: 8.33 | O10: 7 | P10: 6.33
A11: 46239 | B11: 8/5 | C11: 水 | D11: 平日 | E11: 8 | F11: 8 | G11: 9 | H11: 3 | I11: 8 | J11: 7 | K11: 7 | L11: 6 | M11: 8 | N11: 8.33 | O11: 6 | P11: 7
A12: 46240 | B12: 8/6 | C12: 木 | D12: 平日 | E12: 9 | F12: 9 | G12: 9 | H12: 8 | I12: 9 | J12: 7 | K12: 7 | L12: 7 | M12: 8 | N12: 9 | O12: 8 | P12: 7.33
A13: 46241 | B13: 8/7 | C13: 金 | D13: 平日 | E13: 9 | F13: 9 | G13: 9 | H13: 8 | I13: 9 | J13: 8 | K13: 7 | L13: 8 | M13: 8 | N13: 9 | O13: 8.33 | P13: 7.67
A14: 46242 | B14: 8/8 | C14: 土 | D14: 土日 | E14: 9 | F14: 9 | G14: 9 | H14: 6 | I14: 0 | J14: 4 | K14: 7 | L14: 6 | M14: 8 | N14: 9 | O14: 3.33 | P14: 7 | Q14: 9
A15: 46243 | B15: 8/9 | C15: 日 | D15: 土日 | E15: 9 | F15: 9 | G15: 9 | H15: 4 | I15: 0 | J15: 0 | K15: 1 | L15: 7 | M15: 6 | N15: 9 | O15: 1.33 | P15: 4.67 | Q15: 9
A16: 46244 | B16: 8/10 | C16: 月 | D16: 平日 | E16: 9 | F16: 9 | G16: 9 | H16: 7 | I16: 0 | J16: 7 | K16: 8 | L16: 7 | M16: 8 | N16: 9 | O16: 4.67 | P16: 7.67
A17: 46245 | B17: 8/11 | C17: 火 | D17: 山の日 | E17: 8 | F17: 8 | G17: 9 | H17: 0 | I17: 0 | J17: 2 | K17: 3 | L17: 2 | M17: 6 | N17: 8.33 | O17: 0.67 | P17: 3.67 | Q17: 9
A18: 46246 | B18: 8/12 | C18: 水 | D18: 平日 | E18: 9 | F18: 9 | G18: 9 | H18: 8 | I18: 0 | J18: 7 | K18: 6 | L18: 9 | M18: 8 | N18: 9 | O18: 5 | P18: 7.67
A19: 46247 | B19: 8/13 | C19: 木 | D19: 平日 | E19: 8 | F19: 9 | G19: 9 | H19: 3 | I19: 0 | J19: 8 | K19: 4 | L19: 6 | M19: 8 | N19: 8.67 | O19: 3.67 | P19: 6
A20: 46248 | B20: 8/14 | C20: 金 | D20: 平日 | E20: 9 | F20: 8 | G20: 9 | H20: 3 | J20: 4 | K20: 5 | L20: 5 | M20: 6 | N20: 8.67 | O20: 3.5 | P20: 5.33
A21: 46249 | B21: 8/15 | C21: 土 | D21: 土日 | E21: 9 | F21: 9 | G21: 9 | H21: 1 | J21: 0 | K21: 5 | L21: 1 | M21: 7 | N21: 9 | O21: 0.5 | P21: 4.33 | Q21: 9
A22: 46250 | B22: 8/16 | C22: 日 | D22: 土日 | E22: 9 | F22: 9 | G22: 9 | H22: 0 | J22: 0 | K22: 9 | L22: 1 | M22: 8 | N22: 9 | O22: 0 | P22: 6 | Q22: 9
A23: 46251 | B23: 8/17 | C23: 月 | D23: 平日 | E23: 8 | F23: 8 | G23: 8 | H23: 8 | J23: 7 | K23: 7 | L23: 8 | M23: 5 | N23: 8 | O23: 7.5 | P23: 6.67
A24: 46252 | B24: 8/18 | C24: 火 | D24: 平日 | E24: 9 | F24: 9 | G24: 9 | H24: 7 | J24: 9 | K24: 7 | L24: 7 | M24: 9 | N24: 9 | O24: 8 | P24: 7.67
A25: 46253 | B25: 8/19 | C25: 水 | D25: 平日 | E25: 9 | F25: 9 | G25: 9 | H25: 8 | J25: 7 | K25: 7 | L25: 8 | M25: 8 | N25: 9 | O25: 7.5 | P25: 7.67
A26: 46254 | B26: 8/20 | C26: 木 | D26: 平日 | E26: 9 | F26: 9 | G26: 9 | H26: 8 | J26: 7 | K26: 7 | L26: 8 | M26: 7 | N26: 9 | O26: 7.5 | P26: 7.33
A27: 46255 | B27: 8/21 | C27: 金 | D27: 平日 | E27: 9 | F27: 9 | G27: 9 | H27: 8 | J27: 7 | K27: 7 | L27: 8 | M27: 9 | N27: 9 | O27: 7.5 | P27: 8
A28: 46256 | B28: 8/22 | C28: 土 | D28: 土日 | E28: 9 | F28: 9 | G28: 7 | H28: 4 | J28: 2 | K28: 5 | L28: 3 | M28: 8 | N28: 8.33 | O28: 3 | P28: 5.33 | Q28: 9
A29: 46257 | B29: 8/23 | C29: 日 | D29: 土日 | E29: 9 | F29: 9 | G29: 9 | H29: 5 | J29: 3 | K29: 3 | L29: 3 | M29: 9 | N29: 9 | O29: 4 | P29: 5 | Q29: 9
A30: 46258 | B30: 8/24 | C30: 月 | D30: 平日 | E30: 9 | F30: 9 | G30: 8 | H30: 9 | J30: 8 | K30: 9 | L30: 8 | M30: 9 | N30: 8.67 | O30: 8.5 | P30: 8.67
A31: 46259 | B31: 8/25 | C31: 火 | D31: 平日 | E31: 9 | F31: 9 | G31: 9 | H31: 9 | J31: 8 | K31: 9 | L31: 9 | M31: 8 | N31: 9 | O31: 8.5 | P31: 8.67
A32: 46260 | B32: 8/26 | C32: 水 | D32: 平日 | E32: 9 | F32: 9 | G32: 9 | H32: 9 | J32: 8 | K32: 8 | L32: 9 | M32: 9 | N32: 9 | O32: 8.5 | P32: 8.67
A33: 46261 | B33: 8/27 | C33: 木 | D33: 平日 | E33: 9 | F33: 9 | G33: 9 | H33: 6 | J33: 8 | K33: 8 | L33: 7 | M33: 8 | N33: 9 | O33: 7 | P33: 7.67
A34: 46262 | B34: 8/28 | C34: 金 | D34: 平日 | E34: 9 | F34: 9 | G34: 9 | H34: 5 | J34: 7 | K34: 8 | L34: 9 | M34: 9 | N34: 9 | O34: 6 | P34: 8.67
A35: 46263 | B35: 8/29 | C35: 土 | D35: 土日 | E35: 9 | F35: 9 | G35: 9 | H35: 0 | I35: 1 | J35: 4 | K35: 1 | L35: 0 | M35: 8 | N35: 9 | O35: 1.67 | P35: 3 | Q35: 9
A36: 46264 | B36: 8/30 | C36: 日 | D36: 土日 | E36: 6 | G36: 9 | H36: 5 | I36: 3 | J36: 3 | K36: 5 | L36: 3 | M36: 7 | N36: 7.5 | O36: 3.67 | P36: 5 | Q36: 9
A37: 46265 | B37: 8/31 | C37: 月 | D37: 平日 | E37: 7 | G37: 8 | H37: 6 | I37: 9 | J37: 6 | K37: 4 | L37: 8 | M37: 6 | N37: 7.5 | O37: 7 | P37: 6
A38: 46266 | B38: 9/1 | C38: 火 | D38: 平日 | E38: 8 | G38: 8 | H38: 5 | I38: 9 | J38: 8 | K38: 4 | L38: 8 | M38: 7 | N38: 8 | O38: 7.33 | P38: 6.33
A39: 46267 | B39: 9/2 | C39: 水 | D39: 平日 | E39: 9 | G39: 9 | H39: 6 | I39: 9 | J39: 7 | K39: 7 | L39: 7 | M39: 7 | N39: 9 | O39: 7.33 | P39: 7
A40: 46268 | B40: 9/3 | C40: 木 | D40: 平日 | E40: 9 | G40: 9 | H40: 5 | I40: 8 | J40: 6 | K40: 5 | L40: 8 | M40: 9 | N40: 9 | O40: 6.33 | P40: 7.33
...

Sheet 研究に使える時間
A1: 研究に使える時間［時間］（平日に2台とも「運転」の時間）
A2: 土日祝は分析に使わないため空欄。列8・列11は3組の平均
A3: 日付 | B3: 表示用 | C3: 曜日 | D3: 区分 | E3: 8-1と3-1 | F3: 8-2と3-2 | G3: 8-3と3-3 | H3: 11-1と3-1 | I3: 11-2と3-2 | J3: 11-3と3-3 | K3: 列8 | L3: 列11 | M3: 土日祝（グラフの帯）
A4: 46232 | B4: 7/29 | C4: 水 | D4: 平日
A5: 46233 | B5: 7/30 | C5: 木 | D5: 平日 | E5: 8 | F5: 9 | G5: 8 | H5: 8 | I5: 8 | J5: 8 | K5: 8.33 | L5: 8
A6: 46234 | B6: 7/31 | C6: 金 | D6: 平日 | E6: 6 | F6: 8 | G6: 8 | H6: 6 | I6: 8 | J6: 9 | K6: 7.33 | L6: 7.67
A7: 46235 | B7: 8/1 | C7: 土 | D7: 土日 | M7: 9
A8: 46236 | B8: 8/2 | C8: 日 | D8: 土日 | M8: 9
A9: 46237 | B9: 8/3 | C9: 月 | D9: 平日 | E9: 7 | F9: 9 | G9: 8 | H9: 5 | I9: 9 | J9: 7 | K9: 8 | L9: 7
A10: 46238 | B10: 8/4 | C10: 火 | D10: 平日 | E10: 6 | F10: 8 | G10: 6 | H10: 4 | I10: 6 | J10: 7 | K10: 6.67 | L10: 5.67
A11: 46239 | B11: 8/5 | C11: 水 | D11: 平日 | E11: 2 | F11: 7 | G11: 7 | H11: 6 | I11: 5 | J11: 8 | K11: 5.33 | L11: 6.33
A12: 46240 | B12: 8/6 | C12: 木 | D12: 平日 | E12: 8 | F12: 9 | G12: 7 | H12: 7 | I12: 7 | J12: 8 | K12: 8 | L12: 7.33
A13: 46241 | B13: 8/7 | C13: 金 | D13: 平日 | E13: 8 | F13: 9 | G13: 8 | H13: 7 | I13: 8 | J13: 8 | K13: 8.33 | L13: 7.67
A14: 46242 | B14: 8/8 | C14: 土 | D14: 土日 | M14: 9
A15: 46243 | B15: 8/9 | C15: 日 | D15: 土日 | M15: 9
A16: 46244 | B16: 8/10 | C16: 月 | D16: 平日 | E16: 7 | F16: 0 | G16: 7 | H16: 8 | I16: 7 | J16: 8 | K16: 4.67 | L16: 7.67
A17: 46245 | B17: 8/11 | C17: 火 | D17: 山の日 | M17: 9
A18: 46246 | B18: 8/12 | C18: 水 | D18: 平日 | E18: 8 | F18: 0 | G18: 7 | H18: 6 | I18: 9 | J18: 8 | K18: 5 | L18: 7.67
A19: 46247 | B19: 8/13 | C19: 木 | D19: 平日 | E19: 3 | F19: 0 | G19: 8 | H19: 4 | I19: 6 | J19: 8 | K19: 3.67 | L19: 6
A20: 46248 | B20: 8/14 | C20: 金 | D20: 平日 | E20: 3 | G20: 4 | H20: 5 | I20: 5 | J20: 6 | K20: 3.5 | L20: 5.33
A21: 46249 | B21: 8/15 | C21: 土 | D21: 土日 | M21: 9
A22: 46250 | B22: 8/16 | C22: 日 | D22: 土日 | M22: 9
A23: 46251 | B23: 8/17 | C23: 月 | D23: 平日 | E23: 7 | G23: 6 | H23: 6 | I23: 7 | J23: 4 | K23: 6.5 | L23: 5.67
A24: 46252 | B24: 8/18 | C24: 火 | D24: 平日 | E24: 7 | G24: 9 | H24: 7 | I24: 7 | J24: 9 | K24: 8 | L24: 7.67
A25: 46253 | B25: 8/19 | C25: 水 | D25: 平日 | E25: 8 | G25: 7 | H25: 7 | I25: 8 | J25: 8 | K25: 7.5 | L25: 7.67
A26: 46254 | B26: 8/20 | C26: 木 | D26: 平日 | E26: 8 | G26: 7 | H26: 7 | I26: 8 | J26: 7 | K26: 7.5 | L26: 7.33
A27: 46255 | B27: 8/21 | C27: 金 | D27: 平日 | E27: 8 | G27: 7 | H27: 7 | I27: 8 | J27: 9 | K27: 7.5 | L27: 8
A28: 46256 | B28: 8/22 | C28: 土 | D28: 土日 | M28: 9
A29: 46257 | B29: 8/23 | C29: 日 | D29: 土日 | M29: 9
A30: 46258 | B30: 8/24 | C30: 月 | D30: 平日 | E30: 9 | G30: 7 | H30: 9 | I30: 8 | J30: 8 | K30: 8 | L30: 8.33
A31: 46259 | B31: 8/25 | C31: 火 | D31: 平日 | E31: 9 | G31: 8 | H31: 9 | I31: 9 | J31: 8 | K31: 8.5 | L31: 8.67
A32: 46260 | B32: 8/26 | C32: 水 | D32: 平日 | E32: 9 | G32: 8 | H32: 8 | I32: 9 | J32: 9 | K32: 8.5 | L32: 8.67
A33: 46261 | B33: 8/27 | C33: 木 | D33: 平日 | E33: 6 | G33: 8 | H33: 8 | I33: 7 | J33: 8 | K33: 7 | L33: 7.67
A34: 46262 | B34: 8/28 | C34: 金 | D34: 平日 | E34: 5 | G34: 7 | H34: 8 | I34: 9 | J34: 9 | K34: 6 | L34: 8.67
A35: 46263 | B35: 8/29 | C35: 土 | D35: 土日 | M35: 9
A36: 46264 | B36: 8/30 | C36: 日 | D36: 土日 | M36: 9
A37: 46265 | B37: 8/31 | C37: 月 | D37: 平日 | E37: 4 | G37: 5 | H37: 4 | J37: 5 | K37: 4.5 | L37: 4.5
A38: 46266 | B38: 9/1 | C38: 火 | D38: 平日 | E38: 4 | G38: 7 | H38: 3 | J38: 6 | K38: 5.5 | L38: 4.5
A39: 46267 | B39: 9/2 | C39: 水 | D39: 平日 | E39: 6 | G39: 7 | H39: 7 | J39: 7 | K39: 6.5 | L39: 7
A40: 46268 | B40: 9/3 | C40: 木 | D40: 平日 | E40: 5 | G40: 6 | H40: 5 | J40: 9 | K40: 5.5 | L40: 7
...

Sheet 期間別のまとめ
A1: 平日の平均［時間／9時間］と、研究に使える時間が7時間以上の平日の日数
A2: 項目 | B2: 8月 | C2: 9月前半 | D2: 9月後半 | E2: 10月 | F2: 8月：7時間以上の日数 | G2: 9月前半：7時間以上の日数 | H2: 9月後半：7時間以上の日数 | I2: 10月：7時間以上の日数
A3: 期間 | B3: 07/30〜08/31 | C3: 09/01〜09/15 | D3: 09/16〜09/30 | E3: 10/01〜10/13
A4: 稼働時間：列3 | B4: =IFERROR(AVERAGEIFS(日ごとの稼働時間!$N$4:$N$80,日ごとの稼働時間!$A$4:$A$80,">="&DATE(2026,7,30),日ごとの稼働時間!$A$4:$A$80,"<="&DATE(2026,8,31),日ごとの稼働時間!$D$4:$D$80,"平日"),"データなし") -> 8.7804545 | C4: =IFERROR(AVERAGEIFS(日ごとの稼働時間!$N$4:$N$80,日ごとの稼働時間!$A$4:$A$80,">="&DATE(2026,9,1),日ごとの稼働時間!$A$4:$A$80,"<="&DATE(2026,9,15),日ごとの稼働時間!$D$4:$D$80,"平日"),"データなし") -> 6.9090909 | D4: =IFERROR(AVERAGEIFS(日ごとの稼働時間!$N$4:$N$80,日ごとの稼働時間!$A$4:$A$80,">="&DATE(2026,9,16),日ごとの稼働時間!$A$4:$A$80,"<="&DATE(2026,9,30),日ごとの稼働時間!$D$4:$D$80,"平日"),"データなし") -> 4.16625 | E4: =IFERROR(AVERAGEIFS(日ごとの稼働時間!$N$4:$N$80,日ごとの稼働時間!$A$4:$A$80,">="&DATE(2026,10,1),日ごとの稼働時間!$A$4:$A$80,"<="&DATE(2026,10,13),日ごとの稼働時間!$D$4:$D$80,"平日"),"データなし") -> 4.1428571
A5: 稼働時間：列8 | B5: =IFERROR(AVERAGEIFS(日ごとの稼働時間!$O$4:$O$80,日ごとの稼働時間!$A$4:$A$80,">="&DATE(2026,7,30),日ごとの稼働時間!$A$4:$A$80,"<="&DATE(2026,8,31),日ごとの稼働時間!$D$4:$D$80,"平日"),"データなし") -> 6.9695455 | C5: =IFERROR(AVERAGEIFS(日ごとの稼働時間!$O$4:$O$80,日ごとの稼働時間!$A$4:$A$80,">="&DATE(2026,9,1),日ごとの稼働時間!$A$4:$A$80,"<="&DATE(2026,9,15),日ごとの稼働時間!$D$4:$D$80,"平日"),"データなし") -> 6.2109091 | D5: =IFERROR(AVERAGEIFS(日ごとの稼働時間!$O$4:$O$80,日ごとの稼働時間!$A$4:$A$80,">="&DATE(2026,9,16),日ごとの稼働時間!$A$4:$A$80,"<="&DATE(2026,9,30),日ごとの稼働時間!$D$4:$D$80,"平日"),"データなし") -> 5.16625 | E5: =IFERROR(AVERAGEIFS(日ごとの稼働時間!$O$4:$O$80,日ごとの稼働時間!$A$4:$A$80,">="&DATE(2026,10,1),日ごとの稼働時間!$A$4:$A$80,"<="&DATE(2026,10,13),日ごとの稼働時間!$D$4:$D$80,"平日"),"データなし") -> 5.2857143
A6: 稼働時間：列11 | B6: =IFERROR(AVERAGEIFS(日ごとの稼働時間!$P$4:$P$80,日ごとの稼働時間!$A$4:$A$80,">="&DATE(2026,7,30),日ごとの稼働時間!$A$4:$A$80,"<="&DATE(2026,8,31),日ごとの稼働時間!$D$4:$D$80,"平日"),"データなし") -> 7.4254545 | C6: =IFERROR(AVERAGEIFS(日ごとの稼働時間!$P$4:$P$80,日ごとの稼働時間!$A$4:$A$80,">="&DATE(2026,9,1),日ごとの稼働時間!$A$4:$A$80,"<="&DATE(2026,9,15),日ごとの稼働時間!$D$4:$D$80,"平日"),"データなし") -> 5.966 | D6: =IFERROR(AVERAGEIFS(日ごとの稼働時間!$P$4:$P$80,日ごとの稼働時間!$A$4:$A$80,">="&DATE(2026,9,16),日ごとの稼働時間!$A$4:$A$80,"<="&DATE(2026,9,30),日ごとの稼働時間!$D$4:$D$80,"平日"),"データなし") -> データなし | E6: =IFERROR(AVERAGEIFS(日ごとの稼働時間!$P$4:$P$80,日ごとの稼働時間!$A$4:$A$80,">="&DATE(2026,10,1),日ごとの稼働時間!$A$4:$A$80,"<="&DATE(2026,10,13),日ごとの稼働時間!$D$4:$D$80,"平日"),"データなし") -> 5.8333333
A7: 研究に使える：8-1と3-1 | B7: =IFERROR(AVERAGEIFS(研究に使える時間!$E$4:$E$80,研究に使える時間!$A$4:$A$80,">="&DATE(2026,7,30),研究に使える時間!$A$4:$A$80,"<="&DATE(2026,8,31),研究に使える時間!$D$4:$D$80,"平日"),"データなし") -> 6.6363636 | C7: =IFERROR(AVERAGEIFS(研究に使える時間!$E$4:$E$80,研究に使える時間!$A$4:$A$80,">="&DATE(2026,9,1),研究に使える時間!$A$4:$A$80,"<="&DATE(2026,9,15),研究に使える時間!$D$4:$D$80,"平日"),"データなし") -> 3.9090909 | D7: =IFERROR(AVERAGEIFS(研究に使える時間!$E$4:$E$80,研究に使える時間!$A$4:$A$80,">="&DATE(2026,9,16),研究に使える時間!$A$4:$A$80,"<="&DATE(2026,9,30),研究に使える時間!$D$4:$D$80,"平日"),"データなし") -> 2.75 | E7: =IFERROR(AVERAGEIFS(研究に使える時間!$E$4:$E$80,研究に使える時間!$A$4:$A$80,">="&DATE(2026,10,1),研究に使える時間!$A$4:$A$80,"<="&DATE(2026,10,13),研究に使える時間!$D$4:$D$80,"平日"),"データなし") -> 2.7142857 | F7: =IF(COUNTIFS(研究に使える時間!$E$4:$E$80,">=0",研究に使える時間!$A$4:$A$80,">="&DATE(2026,7,30),研究に使える時間!$A$4:$A$80,"<="&DATE(2026,8,31),研究に使える時間!$D$4:$D$80,"平日")=0,"データなし",COUNTIFS(研究に使える時間!$E$4:$E$80,">=7",研究に使える時間!$A$4:$A$80,">="&DATE(2026,7,30),研究に使える時間!$A$4:$A$80,"<="&DATE(2026,8,31),研究に使える時間!$D$4:$D$80,"平日")) -> 14 | G7: =IF(COUNTIFS(研究に使える時間!$E$4:$E$80,">=0",研究に使える時間!$A$4:$A$80,">="&DATE(2026,9,1),研究に使える時間!$A$4:$A$80,"<="&DATE(2026,9,15),研究に使える時間!$D$4:$D$80,"平日")=0,"データなし",COUNTIFS(研究に使える時間!$E$4:$E$80,">=7",研究に使える時間!$A$4:$A$80,">="&DATE(2026,9,1),研究に使える時間!$A$4:$A$80,"<="&DATE(2026,9,15),研究に使える時間!$D$4:$D$80,"平日")) -> 1 | H7: =IF(COUNTIFS(研究に使える時間!$E$4:$E$80,">=0",研究に使える時間!$A$4:$A$80,">="&DATE(2026,9,16),研究に使える時間!$A$4:$A$80,"<="&DATE(2026,9,30),研究に使える時間!$D$4:$D$80,"平日")=0,"データなし",COUNTIFS(研究に使える時間!$E$4:$E$80,">=7",研究に使える時間!$A$4:$A$80,">="&DATE(2026,9,16),研究に使える時間!$A$4:$A$80,"<="&DATE(2026,9,30),研究に使える時間!$D$4:$D$80,"平日")) -> 2 | I7: =IF(COUNTIFS(研究に使える時間!$E$4:$E$80,">=0",研究に使える時間!$A$4:$A$80,">="&DATE(2026,10,1),研究に使える時間!$A$4:$A$80,"<="&DATE(2026,10,13),研究に使える時間!$D$4:$D$80,"平日")=0,"データなし",COUNTIFS(研究に使える時間!$E$4:$E$80,">=7",研究に使える時間!$A$4:$A$80,">="&DATE(2026,10,1),研究に使える時間!$A$4:$A$80,"<="&DATE(2026,10,13),研究に使える時間!$D$4:$D$80,"平日")) -> 1
A8: 研究に使える：8-2と3-2 | B8: =IFERROR(AVERAGEIFS(研究に使える時間!$F$4:$F$80,研究に使える時間!$A$4:$A$80,">="&DATE(2026,7,30),研究に使える時間!$A$4:$A$80,"<="&DATE(2026,8,31),研究に使える時間!$D$4:$D$80,"平日"),"データなし") -> 5.9 | C8: =IFERROR(AVERAGEIFS(研究に使える時間!$F$4:$F$80,研究に使える時間!$A$4:$A$80,">="&DATE(2026,9,1),研究に使える時間!$A$4:$A$80,"<="&DATE(2026,9,15),研究に使える時間!$D$4:$D$80,"平日"),"データなし") -> 5 | D8: =IFERROR(AVERAGEIFS(研究に使える時間!$F$4:$F$80,研究に使える時間!$A$4:$A$80,">="&DATE(2026,9,16),研究に使える時間!$A$4:$A$80,"<="&DATE(2026,9,30),研究に使える時間!$D$4:$D$80,"平日"),"データなし") -> 3.6 | E8: =IFERROR(AVERAGEIFS(研究に使える時間!$F$4:$F$80,研究に使える時間!$A$4:$A$80,">="&DATE(2026,10,1),研究に使える時間!$A$4:$A$80,"<="&DATE(2026,10,13),研究に使える時間!$D$4:$D$80,"平日"),"データなし") -> 4.1428571 | F8: =IF(COUNTIFS(研究に使える時間!$F$4:$F$80,">=0",研究に使える時間!$A$4:$A$80,">="&DATE(2026,7,30),研究に使える時間!$A$4:$A$80,"<="&DATE(2026,8,31),研究に使える時間!$D$4:$D$80,"平日")=0,"データなし",COUNTIFS(研究に使える時間!$F$4:$F$80,">=7",研究に使える時間!$A$4:$A$80,">="&DATE(2026,7,30),研究に使える時間!$A$4:$A$80,"<="&DATE(2026,8,31),研究に使える時間!$D$4:$D$80,"平日")) -> 7 | G8: =IF(COUNTIFS(研究に使える時間!$F$4:$F$80,">=0",研究に使える時間!$A$4:$A$80,">="&DATE(2026,9,1),研究に使える時間!$A$4:$A$80,"<="&DATE(2026,9,15),研究に使える時間!$D$4:$D$80,"平日")=0,"データなし",COUNTIFS(研究に使える時間!$F$4:$F$80,">=7",研究に使える時間!$A$4:$A$80,">="&DATE(2026,9,1),研究に使える時間!$A$4:$A$80,"<="&DATE(2026,9,15),研究に使える時間!$D$4:$D$80,"平日")) -> 3 | H8: =IF(COUNTIFS(研究に使える時間!$F$4:$F$80,">=0",研究に使える時間!$A$4:$A$80,">="&DATE(2026,9,16),研究に使える時間!$A$4:$A$80,"<="&DATE(2026,9,30),研究に使える時間!$D$4:$D$80,"平日")=0,"データなし",COUNTIFS(研究に使える時間!$F$4:$F$80,">=7",研究に使える時間!$A$4:$A$80,">="&DATE(2026,9,16),研究に使える時間!$A$4:$A$80,"<="&DATE(2026,9,30),研究に使える時間!$D$4:$D$80,"平日")) -> 2 | I8: =IF(COUNTIFS(研究に使える時間!$F$4:$F$80,">=0",研究に使える時間!$A$4:$A$80,">="&DATE(2026,10,1),研究に使える時間!$A$4:$A$80,"<="&DATE(2026,10,13),研究に使える時間!$D$4:$D$80,"平日")=0,"データなし",COUNTIFS(研究に使える時間!$F$4:$F$80,">=7",研究に使える時間!$A$4:$A$80,">="&DATE(2026,10,1),研究に使える時間!$A$4:$A$80,"<="&DATE(2026,10,13),研究に使える時間!$D$4:$D$80,"平日")) -> 1
A9: 研究に使える：8-3と3-3 | B9: =IFERROR(AVERAGEIFS(研究に使える時間!$G$4:$G$80,研究に使える時間!$A$4:$A$80,">="&DATE(2026,7,30),研究に使える時間!$A$4:$A$80,"<="&DATE(2026,8,31),研究に使える時間!$D$4:$D$80,"平日"),"データなし") -> 7.1363636 | C9: =IFERROR(AVERAGEIFS(研究に使える時間!$G$4:$G$80,研究に使える時間!$A$4:$A$80,">="&DATE(2026,9,1),研究に使える時間!$A$4:$A$80,"<="&DATE(2026,9,15),研究に使える時間!$D$4:$D$80,"平日"),"データなし") -> 5.5454545 | D9: =IFERROR(AVERAGEIFS(研究に使える時間!$G$4:$G$80,研究に使える時間!$A$4:$A$80,">="&DATE(2026,9,16),研究に使える時間!$A$4:$A$80,"<="&DATE(2026,9,30),研究に使える時間!$D$4:$D$80,"平日"),"データなし") -> 3.875 | E9: =IFERROR(AVERAGEIFS(研究に使える時間!$G$4:$G$80,研究に使える時間!$A$4:$A$80,">="&DATE(2026,10,1),研究に使える時間!$A$4:$A$80,"<="&DATE(2026,10,13),研究に使える時間!$D$4:$D$80,"平日"),"データなし") -> 4 | F9: =IF(COUNTIFS(研究に使える時間!$G$4:$G$80,">=0",研究に使える時間!$A$4:$A$80,">="&DATE(2026,7,30),研究に使える時間!$A$4:$A$80,"<="&DATE(2026,8,31),研究に使える時間!$D$4:$D$80,"平日")=0,"データなし",COUNTIFS(研究に使える時間!$G$4:$G$80,">=7",研究に使える時間!$A$4:$A$80,">="&DATE(2026,7,30),研究に使える時間!$A$4:$A$80,"<="&DATE(2026,8,31),研究に使える時間!$D$4:$D$80,"平日")) -> 18 | G9: =IF(COUNTIFS(研究に使える時間!$G$4:$G$80,">=0",研究に使える時間!$A$4:$A$80,">="&DATE(2026,9,1),研究に使える時間!$A$4:$A$80,"<="&DATE(2026,9,15),研究に使える時間!$D$4:$D$80,"平日")=0,"データなし",COUNTIFS(研究に使える時間!$G$4:$G$80,">=7",研究に使える時間!$A$4:$A$80,">="&DATE(2026,9,1),研究に使える時間!$A$4:$A$80,"<="&DATE(2026,9,15),研究に使える時間!$D$4:$D$80,"平日")) -> 3 | H9: =IF(COUNTIFS(研究に使える時間!$G$4:$G$80,">=0",研究に使える時間!$A$4:$A$80,">="&DATE(2026,9,16),研究に使える時間!$A$4:$A$80,"<="&DATE(2026,9,30),研究に使える時間!$D$4:$D$80,"平日")=0,"データなし",COUNTIFS(研究に使える時間!$G$4:$G$80,">=7",研究に使える時間!$A$4:$A$80,">="&DATE(2026,9,16),研究に使える時間!$A$4:$A$80,"<="&DATE(2026,9,30),研究に使える時間!$D$4:$D$80,"平日")) -> 3 | I9: =IF(COUNTIFS(研究に使える時間!$G$4:$G$80,">=0",研究に使える時間!$A$4:$A$80,">="&DATE(2026,10,1),研究に使える時間!$A$4:$A$80,"<="&DATE(2026,10,13),研究に使える時間!$D$4:$D$80,"平日")=0,"データなし",COUNTIFS(研究に使える時間!$G$4:$G$80,">=7",研究に使える時間!$A$4:$A$80,">="&DATE(2026,10,1),研究に使える時間!$A$4:$A$80,"<="&DATE(2026,10,13),研究に使える時間!$D$4:$D$80,"平日")) -> 1
A10: 研究に使える：11-1と3-1 | B10: =IFERROR(AVERAGEIFS(研究に使える時間!$H$4:$H$80,研究に使える時間!$A$4:$A$80,">="&DATE(2026,7,30),研究に使える時間!$A$4:$A$80,"<="&DATE(2026,8,31),研究に使える時間!$D$4:$D$80,"平日"),"データなし") -> 6.6363636 | C10: =IFERROR(AVERAGEIFS(研究に使える時間!$H$4:$H$80,研究に使える時間!$A$4:$A$80,">="&DATE(2026,9,1),研究に使える時間!$A$4:$A$80,"<="&DATE(2026,9,15),研究に使える時間!$D$4:$D$80,"平日"),"データなし") -> 3.3 | D10: =IFERROR(AVERAGEIFS(研究に使える時間!$H$4:$H$80,研究に使える時間!$A$4:$A$80,">="&DATE(2026,9,16),研究に使える時間!$A$4:$A$80,"<="&DATE(2026,9,30),研究に使える時間!$D$4:$D$80,"平日"),"データなし") -> データなし | E10: =IFERROR(AVERAGEIFS(研究に使える時間!$H$4:$H$80,研究に使える時間!$A$4:$A$80,">="&DATE(2026,10,1),研究に使える時間!$A$4:$A$80,"<="&DATE(2026,10,13),研究に使える時間!$D$4:$D$80,"平日"),"データなし") -> 2.1666667 | F10: =IF(COUNTIFS(研究に使える時間!$H$4:$H$80,">=0",研究に使える時間!$A$4:$A$80,">="&DATE(2026,7,30),研究に使える時間!$A$4:$A$80,"<="&DATE(2026,8,31),研究に使える時間!$D$4:$D$80,"平日")=0,"データなし",COUNTIFS(研究に使える時間!$H$4:$H$80,">=7",研究に使える時間!$A$4:$A$80,">="&DATE(2026,7,30),研究に使える時間!$A$4:$A$80,"<="&DATE(2026,8,31),研究に使える時間!$D$4:$D$80,"平日")) -> 13 | G10: =IF(COUNTIFS(研究に使える時間!$H$4:$H$80,">=0",研究に使える時間!$A$4:$A$80,">="&DATE(2026,9,1),研究に使える時間!$A$4:$A$80,"<="&DATE(2026,9,15),研究に使える時間!$D$4:$D$80,"平日")=0,"データなし",COUNTIFS(研究に使える時間!$H$4:$H$80,">=7",研究に使える時間!$A$4:$A$80,">="&DATE(2026,9,1),研究に使える時間!$A$4:$A$80,"<="&DATE(2026,9,15),研究に使える時間!$D$4:$D$80,"平日")) -> 1 | H10: =IF(COUNTIFS(研究に使える時間!$H$4:$H$80,">=0",研究に使える時間!$A$4:$A$80,">="&DATE(2026,9,16),研究に使える時間!$A$4:$A$80,"<="&DATE(2026,9,30),研究に使える時間!$D$4:$D$80,"平日")=0,"データなし",COUNTIFS(研究に使える時間!$H$4:$H$80,">=7",研究に使える時間!$A$4:$A$80,">="&DATE(2026,9,16),研究に使える時間!$A$4:$A$80,"<="&DATE(2026,9,30),研究に使える時間!$D$4:$D$80,"平日")) -> データなし | I10: =IF(COUNTIFS(研究に使える時間!$H$4:$H$80,">=0",研究に使える時間!$A$4:$A$80,">="&DATE(2026,10,1),研究に使える時間!$A$4:$A$80,"<="&DATE(2026,10,13),研究に使える時間!$D$4:$D$80,"平日")=0,"データなし",COUNTIFS(研究に使える時間!$H$4:$H$80,">=7",研究に使える時間!$A$4:$A$80,">="&DATE(2026,10,1),研究に使える時間!$A$4:$A$80,"<="&DATE(2026,10,13),研究に使える時間!$D$4:$D$80,"平日")) -> 0
A11: 研究に使える：11-2と3-2 | B11: =IFERROR(AVERAGEIFS(研究に使える時間!$I$4:$I$80,研究に使える時間!$A$4:$A$80,">="&DATE(2026,7,30),研究に使える時間!$A$4:$A$80,"<="&DATE(2026,8,31),研究に使える時間!$D$4:$D$80,"平日"),"データなし") -> 7.5238095 | C11: =IFERROR(AVERAGEIFS(研究に使える時間!$I$4:$I$80,研究に使える時間!$A$4:$A$80,">="&DATE(2026,9,1),研究に使える時間!$A$4:$A$80,"<="&DATE(2026,9,15),研究に使える時間!$D$4:$D$80,"平日"),"データなし") -> 5 | D11: =IFERROR(AVERAGEIFS(研究に使える時間!$I$4:$I$80,研究に使える時間!$A$4:$A$80,">="&DATE(2026,9,16),研究に使える時間!$A$4:$A$80,"<="&DATE(2026,9,30),研究に使える時間!$D$4:$D$80,"平日"),"データなし") -> データなし | E11: =IFERROR(AVERAGEIFS(研究に使える時間!$I$4:$I$80,研究に使える時間!$A$4:$A$80,">="&DATE(2026,10,1),研究に使える時間!$A$4:$A$80,"<="&DATE(2026,10,13),研究に使える時間!$D$4:$D$80,"平日"),"データなし") -> 3.6666667 | F11: =IF(COUNTIFS(研究に使える時間!$I$4:$I$80,">=0",研究に使える時間!$A$4:$A$80,">="&DATE(2026,7,30),研究に使える時間!$A$4:$A$80,"<="&DATE(2026,8,31),研究に使える時間!$D$4:$D$80,"平日")=0,"データなし",COUNTIFS(研究に使える時間!$I$4:$I$80,">=7",研究に使える時間!$A$4:$A$80,">="&DATE(2026,7,30),研究に使える時間!$A$4:$A$80,"<="&DATE(2026,8,31),研究に使える時間!$D$4:$D$80,"平日")) -> 17 | G11: =IF(COUNTIFS(研究に使える時間!$I$4:$I$80,">=0",研究に使える時間!$A$4:$A$80,">="&DATE(2026,9,1),研究に使える時間!$A$4:$A$80,"<="&DATE(2026,9,15),研究に使える時間!$D$4:$D$80,"平日")=0,"データなし",COUNTIFS(研究に使える時間!$I$4:$I$80,">=7",研究に使える時間!$A$4:$A$80,">="&DATE(2026,9,1),研究に使える時間!$A$4:$A$80,"<="&DATE(2026,9,15),研究に使える時間!$D$4:$D$80,"平日")) -> 1 | H11: =IF(COUNTIFS(研究に使える時間!$I$4:$I$80,">=0",研究に使える時間!$A$4:$A$80,">="&DATE(2026,9,16),研究に使える時間!$A$4:$A$80,"<="&DATE(2026,9,30),研究に使える時間!$D$4:$D$80,"平日")=0,"データなし",COUNTIFS(研究に使える時間!$I$4:$I$80,">=7",研究に使える時間!$A$4:$A$80,">="&DATE(2026,9,16),研究に使える時間!$A$4:$A$80,"<="&DATE(2026,9,30),研究に使える時間!$D$4:$D$80,"平日")) -> データなし | I11: =IF(COUNTIFS(研究に使える時間!$I$4:$I$80,">=0",研究に使える時間!$A$4:$A$80,">="&DATE(2026,10,1),研究に使える時間!$A$4:$A$80,"<="&DATE(2026,10,13),研究に使える時間!$D$4:$D$80,"平日")=0,"データなし",COUNTIFS(研究に使える時間!$I$4:$I$80,">=7",研究に使える時間!$A$4:$A$80,">="&DATE(2026,10,1),研究に使える時間!$A$4:$A$80,"<="&DATE(2026,10,13),研究に使える時間!$D$4:$D$80,"平日")) -> 0
A12: 研究に使える：11-3と3-3 | B12: =IFERROR(AVERAGEIFS(研究に使える時間!$J$4:$J$80,研究に使える時間!$A$4:$A$80,">="&DATE(2026,7,30),研究に使える時間!$A$4:$A$80,"<="&DATE(2026,8,31),研究に使える時間!$D$4:$D$80,"平日"),"データなし") -> 7.6818182 | C12: =IFERROR(AVERAGEIFS(研究に使える時間!$J$4:$J$80,研究に使える時間!$A$4:$A$80,">="&DATE(2026,9,1),研究に使える時間!$A$4:$A$80,"<="&DATE(2026,9,15),研究に使える時間!$D$4:$D$80,"平日"),"データなし") -> 6.1 | D12: =IFERROR(AVERAGEIFS(研究に使える時間!$J$4:$J$80,研究に使える時間!$A$4:$A$80,">="&DATE(2026,9,16),研究に使える時間!$A$4:$A$80,"<="&DATE(2026,9,30),研究に使える時間!$D$4:$D$80,"平日"),"データなし") -> データなし | E12: =IFERROR(AVERAGEIFS(研究に使える時間!$J$4:$J$80,研究に使える時間!$A$4:$A$80,">="&DATE(2026,10,1),研究に使える時間!$A$4:$A$80,"<="&DATE(2026,10,13),研究に使える時間!$D$4:$D$80,"平日"),"データなし") -> 3.1666667 | F12: =IF(COUNTIFS(研究に使える時間!$J$4:$J$80,">=0",研究に使える時間!$A$4:$A$80,">="&DATE(2026,7,30),研究に使える時間!$A$4:$A$80,"<="&DATE(2026,8,31),研究に使える時間!$D$4:$D$80,"平日")=0,"データなし",COUNTIFS(研究に使える時間!$J$4:$J$80,">=7",研究に使える時間!$A$4:$A$80,">="&DATE(2026,7,30),研究に使える時間!$A$4:$A$80,"<="&DATE(2026,8,31),研究に使える時間!$D$4:$D$80,"平日")) -> 19 | G12: =IF(COUNTIFS(研究に使える時間!$J$4:$J$80,">=0",研究に使える時間!$A$4:$A$80,">="&DATE(2026,9,1),研究に使える時間!$A$4:$A$80,"<="&DATE(2026,9,15),研究に使える時間!$D$4:$D$80,"平日")=0,"データなし",COUNTIFS(研究に使える時間!$J$4:$J$80,">=7",研究に使える時間!$A$4:$A$80,">="&DATE(2026,9,1),研究に使える時間!$A$4:$A$80,"<="&DATE(2026,9,15),研究に使える時間!$D$4:$D$80,"平日")) -> 4 | H12: =IF(COUNTIFS(研究に使える時間!$J$4:$J$80,">=0",研究に使える時間!$A$4:$A$80,">="&DATE(2026,9,16),研究に使える時間!$A$4:$A$80,"<="&DATE(2026,9,30),研究に使える時間!$D$4:$D$80,"平日")=0,"データなし",COUNTIFS(研究に使える時間!$J$4:$J$80,">=7",研究に使える時間!$A$4:$A$80,">="&DATE(2026,9,16),研究に使える時間!$A$4:$A$80,"<="&DATE(2026,9,30),研究に使える時間!$D$4:$D$80,"平日")) -> データなし | I12: =IF(COUNTIFS(研究に使える時間!$J$4:$J$80,">=0",研究に使える時間!$A$4:$A$80,">="&DATE(2026,10,1),研究に使える時間!$A$4:$A$80,"<="&DATE(2026,10,13),研究に使える時間!$D$4:$D$80,"平日")=0,"データなし",COUNTIFS(研究に使える時間!$J$4:$J$80,">=7",研究に使える時間!$A$4:$A$80,">="&DATE(2026,10,1),研究に使える時間!$A$4:$A$80,"<="&DATE(2026,10,13),研究に使える時間!$D$4:$D$80,"平日")) -> 0
A13: 研究に使える：列8（3組平均） | B13: =IFERROR(AVERAGEIFS(研究に使える時間!$K$4:$K$80,研究に使える時間!$A$4:$A$80,">="&DATE(2026,7,30),研究に使える時間!$A$4:$A$80,"<="&DATE(2026,8,31),研究に使える時間!$D$4:$D$80,"平日"),"データなし") -> 6.7422727 | C13: =IFERROR(AVERAGEIFS(研究に使える時間!$K$4:$K$80,研究に使える時間!$A$4:$A$80,">="&DATE(2026,9,1),研究に使える時間!$A$4:$A$80,"<="&DATE(2026,9,15),研究に使える時間!$D$4:$D$80,"平日"),"データなし") -> 4.8027273 | D13: =IFERROR(AVERAGEIFS(研究に使える時間!$K$4:$K$80,研究に使える時間!$A$4:$A$80,">="&DATE(2026,9,16),研究に使える時間!$A$4:$A$80,"<="&DATE(2026,9,30),研究に使える時間!$D$4:$D$80,"平日"),"データなし") -> 3.25 | E13: =IFERROR(AVERAGEIFS(研究に使える時間!$K$4:$K$80,研究に使える時間!$A$4:$A$80,">="&DATE(2026,10,1),研究に使える時間!$A$4:$A$80,"<="&DATE(2026,10,13),研究に使える時間!$D$4:$D$80,"平日"),"データなし") -> 3.6185714
A14: 研究に使える：列11（3組平均） | B14: =IFERROR(AVERAGEIFS(研究に使える時間!$L$4:$L$80,研究に使える時間!$A$4:$A$80,">="&DATE(2026,7,30),研究に使える時間!$A$4:$A$80,"<="&DATE(2026,8,31),研究に使える時間!$D$4:$D$80,"平日"),"データなし") -> 7.2359091 | C14: =IFERROR(AVERAGEIFS(研究に使える時間!$L$4:$L$80,研究に使える時間!$A$4:$A$80,">="&DATE(2026,9,1),研究に使える時間!$A$4:$A$80,"<="&DATE(2026,9,15),研究に使える時間!$D$4:$D$80,"平日"),"データなし") -> 4.866 | D14: =IFERROR(AVERAGEIFS(研究に使える時間!$L$4:$L$80,研究に使える時間!$A$4:$A$80,">="&DATE(2026,9,16),研究に使える時間!$A$4:$A$80,"<="&DATE(2026,9,30),研究に使える時間!$D$4:$D$80,"平日"),"データなし") -> データなし | E14: =IFERROR(AVERAGEIFS(研究に使える時間!$L$4:$L$80,研究に使える時間!$A$4:$A$80,">="&DATE(2026,10,1),研究に使える時間!$A$4:$A$80,"<="&DATE(2026,10,13),研究に使える時間!$D$4:$D$80,"平日"),"データなし") -> 3.0016667

Sheet グラフ
A1: グラフ（元データは「日ごとの稼働時間」「研究に使える時間」。灰色の帯は土日祝）
