Workbook

Sheet 判定条件
B1: 室外機の稼働状況による、分析に使える日・時間帯の判定
B2: 対象：2026/7/29〜10/13（1分値）。芋緑化ありの室外機と、同じ区画の芋緑化なし（OACP-3）の室外機を1組とし、2台とも運転している時間だけを「利用可」とする。黄色のセルを変えると、すべての判定が更新される。
B4: 段階 | C4: 値 | D4: 内容
B5: ① 1分ごとの運転判定（Pythonで計算） | C5: 1.0℃以上 | D5: 排気温度 − 吸気温度（3方位の平均）の10分の移動中央値がこの値以上なら「運転中」。停止中は約0℃、運転中は2〜10℃に分かれ、その谷が1℃付近にある。11-3は北側を除く2方位。3-1北側吸気は異常期間を除く（「データの不具合」）
B6: ② 1時間の判定に必要な有効データ［分］ | C6: 48 | D6: 1時間のうち、①の判定ができた分がこれ未満なら「判定不能」（これまでの1時間平均の基準と同じ）
B7: ③ 室外機が「運転」とみなす割合 | C7: 0.8 | D7: 有効な分のうち、運転中の分がこの割合以上なら「運転」
B8: ④ 室外機が「停止」とみなす割合 | C8: 0.2 | D8: 運転中の分がこの割合以下なら「停止」。③と④の間は「断続」（1時間の中で運転と停止を繰り返す）
B9: ⑤ 組が「利用可」となる、2台とも運転中の分数［分］ | C9: 30 | D9: その1時間に、2台とも運転中の分がこれ以上あれば「利用可」。吸気温度差はこの「2台とも運転中」の分だけで平均する
B10: ⑥ 日中の始まり［時台］ | C10: 9 | D10: 日ごとの判定で数える時間帯の始まり（これまでの「日中」と同じ9時台）
B11: ⑦ 日中の終わり［時台］ | C11: 17 | D11: 日ごとの判定で数える時間帯の終わり（17時台＝18時まで）
B12: ⑧ 日として使うのに必要な利用可の時間数 | C12: 7 | D12: ⑥〜⑦の9時間のうち、利用可がこの時間数以上ある日を「利用可」の日とする（これまでの「9時間中7時間以上」と同じ）
B14: 判定の名前
B15: 利用可 | D15: 2台とも運転中の分が⑤以上。分析に使う
B16: 両方停止 | D16: 2台とも停止。運転中の比較には使わない（夜間・休日など）
B17: 運転がそろわない | D17: 片方だけ運転、または断続で2台とも運転中の分が⑤未満。使わない
B18: 判定不能 | D18: 排気温度・吸気温度が欠けていて運転状態がわからない。使わない
B20: 結果のまとめ（7/30〜10/13、日中）
B21: 組 | C21: 利用可の時間数 | D21: 利用可の日数（⑧を満たす日）
B22: 8-1と3-1 | C22: =COUNTIFS(時間ごとの判定!$A$3:$A$1850,">="&DATE(2026,7,30),時間ごとの判定!$B$3:$B$1850,">="&判定条件!$C$10,時間ごとの判定!$B$3:$B$1850,"<="&判定条件!$C$11,時間ごとの判定!$AH$3:$AH$1850,"利用可") -> 411 | D22: =COUNTIFS(日ごとの判定!$E$4:$E$79,"利用可") -> 40
B23: 8-2と3-2 | C23: =COUNTIFS(時間ごとの判定!$A$3:$A$1850,">="&DATE(2026,7,30),時間ごとの判定!$B$3:$B$1850,">="&判定条件!$C$10,時間ごとの判定!$B$3:$B$1850,"<="&判定条件!$C$11,時間ごとの判定!$AK$3:$AK$1850,"利用可") -> 211 | D23: =COUNTIFS(日ごとの判定!$G$4:$G$79,"利用可") -> 15
B24: 8-3と3-3 | C24: =COUNTIFS(時間ごとの判定!$A$3:$A$1850,">="&DATE(2026,7,30),時間ごとの判定!$B$3:$B$1850,">="&判定条件!$C$10,時間ごとの判定!$B$3:$B$1850,"<="&判定条件!$C$11,時間ごとの判定!$AN$3:$AN$1850,"利用可") -> 445 | D24: =COUNTIFS(日ごとの判定!$I$4:$I$79,"利用可") -> 41
B25: 11-1と3-1 | C25: =COUNTIFS(時間ごとの判定!$A$3:$A$1850,">="&DATE(2026,7,30),時間ごとの判定!$B$3:$B$1850,">="&判定条件!$C$10,時間ごとの判定!$B$3:$B$1850,"<="&判定条件!$C$11,時間ごとの判定!$AQ$3:$AQ$1850,"利用可") -> 400 | D25: =COUNTIFS(日ごとの判定!$K$4:$K$79,"利用可") -> 41
B26: 11-2と3-2 | C26: =COUNTIFS(時間ごとの判定!$A$3:$A$1850,">="&DATE(2026,7,30),時間ごとの判定!$B$3:$B$1850,">="&判定条件!$C$10,時間ごとの判定!$B$3:$B$1850,"<="&判定条件!$C$11,時間ごとの判定!$AT$3:$AT$1850,"利用可") -> 338 | D26: =COUNTIFS(日ごとの判定!$M$4:$M$79,"利用可") -> 31
B27: 11-3と3-3 | C27: =COUNTIFS(時間ごとの判定!$A$3:$A$1850,">="&DATE(2026,7,30),時間ごとの判定!$B$3:$B$1850,">="&判定条件!$C$10,時間ごとの判定!$B$3:$B$1850,"<="&判定条件!$C$11,時間ごとの判定!$AW$3:$AW$1850,"利用可") -> 473 | D27: =COUNTIFS(日ごとの判定!$O$4:$O$79,"利用可") -> 50
B28: 列8（3区画とも利用可の日） | C28: =COUNTIFS(時間ごとの判定!$A$3:$A$1850,">="&DATE(2026,7,30),時間ごとの判定!$B$3:$B$1850,">="&判定条件!$C$10,時間ごとの判定!$B$3:$B$1850,"<="&判定条件!$C$11,時間ごとの判定!$AX$3:$AX$1850,"利用可") -> 153 | D28: =COUNTIFS(日ごとの判定!$P$4:$P$79,"利用可") -> 13
B29: 列11（3区画とも利用可の日） | C29: =COUNTIFS(時間ごとの判定!$A$3:$A$1850,">="&DATE(2026,7,30),時間ごとの判定!$B$3:$B$1850,">="&判定条件!$C$10,時間ごとの判定!$B$3:$B$1850,"<="&判定条件!$C$11,時間ごとの判定!$AY$3:$AY$1850,"利用可") -> 301 | D29: =COUNTIFS(日ごとの判定!$Q$4:$Q$79,"利用可") -> 28
B30: 7/29は設置当日のため数えない。列8・列11の時間数は、その1時間に3組とも利用可の時間

Sheet 日ごとの判定
A1: 日付 | B1: 曜日 | C1: 区分 | D1: 8-1と3-1 | F1: 8-2と3-2 | H1: 8-3と3-3 | J1: 11-1と3-1 | L1: 11-2と3-2 | N1: 11-3と3-3 | P1: 列8（3区画とも利用可の日） | Q1: 列11（3区画とも利用可の日） | R1: 備考（データの欠け）
D2: 日中の利用可［時間］ | E2: 日の判定 | F2: 日中の利用可［時間］ | G2: 日の判定 | H2: 日中の利用可［時間］ | I2: 日の判定 | J2: 日中の利用可［時間］ | K2: 日の判定 | L2: 日中の利用可［時間］ | M2: 日の判定 | N2: 日中の利用可［時間］ | O2: 日の判定
A3: 46232 | B3: 水 | C3: 平日 | D3: =COUNTIFS(時間ごとの判定!$A$3:$A$1850,$A3,時間ごとの判定!$B$3:$B$1850,">="&判定条件!$C$10,時間ごとの判定!$B$3:$B$1850,"<="&判定条件!$C$11,時間ごとの判定!$AH$3:$AH$1850,"利用可") -> 0 | E3: =IF(D3>=判定条件!$C$12,"利用可","不可") -> 不可 | F3: =COUNTIFS(時間ごとの判定!$A$3:$A$1850,$A3,時間ごとの判定!$B$3:$B$1850,">="&判定条件!$C$10,時間ごとの判定!$B$3:$B$1850,"<="&判定条件!$C$11,時間ごとの判定!$AK$3:$AK$1850,"利用可") -> 1 | G3: =IF(F3>=判定条件!$C$12,"利用可","不可") -> 不可 | H3: =COUNTIFS(時間ごとの判定!$A$3:$A$1850,$A3,時間ごとの判定!$B$3:$B$1850,">="&判定条件!$C$10,時間ごとの判定!$B$3:$B$1850,"<="&判定条件!$C$11,時間ごとの判定!$AN$3:$AN$1850,"利用可") -> 1 | I3: =IF(H3>=判定条件!$C$12,"利用可","不可") -> 不可 | J3: =COUNTIFS(時間ごとの判定!$A$3:$A$1850,$A3,時間ごとの判定!$B$3:$B$1850,">="&判定条件!$C$10,時間ごとの判定!$B$3:$B$1850,"<="&判定条件!$C$11,時間ごとの判定!$AQ$3:$AQ$1850,"利用可") -> 0 | K3: =IF(J3>=判定条件!$C$12,"利用可","不可") -> 不可 | L3: =COUNTIFS(時間ごとの判定!$A$3:$A$1850,$A3,時間ごとの判定!$B$3:$B$1850,">="&判定条件!$C$10,時間ごとの判定!$B$3:$B$1850,"<="&判定条件!$C$11,時間ごとの判定!$AT$3:$AT$1850,"利用可") -> 1 | M3: =IF(L3>=判定条件!$C$12,"利用可","不可") -> 不可 | N3: =COUNTIFS(時間ごとの判定!$A$3:$A$1850,$A3,時間ごとの判定!$B$3:$B$1850,">="&判定条件!$C$10,時間ごとの判定!$B$3:$B$1850,"<="&判定条件!$C$11,時間ごとの判定!$AW$3:$AW$1850,"利用可") -> 1 | O3: =IF(N3>=判定条件!$C$12,"利用可","不可") -> 不可 | P3: =IF(AND(E3="利用可",G3="利用可",I3="利用可"),"利用可","不可") -> 不可 | Q3: =IF(AND(K3="利用可",M3="利用可",O3="利用可"),"利用可","不可") -> 不可 | R3: 設置当日（16:14から記録）。使わない
A4: 46233 | B4: 木 | C4: 平日 | D4: =COUNTIFS(時間ごとの判定!$A$3:$A$1850,$A4,時間ごとの判定!$B$3:$B$1850,">="&判定条件!$C$10,時間ごとの判定!$B$3:$B$1850,"<="&判定条件!$C$11,時間ごとの判定!$AH$3:$AH$1850,"利用可") -> 9 | E4: =IF(D4>=判定条件!$C$12,"利用可","不可") -> 利用可 | F4: =COUNTIFS(時間ごとの判定!$A$3:$A$1850,$A4,時間ごとの判定!$B$3:$B$1850,">="&判定条件!$C$10,時間ごとの判定!$B$3:$B$1850,"<="&判定条件!$C$11,時間ごとの判定!$AK$3:$AK$1850,"利用可") -> 9 | G4: =IF(F4>=判定条件!$C$12,"利用可","不可") -> 利用可 | H4: =COUNTIFS(時間ごとの判定!$A$3:$A$1850,$A4,時間ごとの判定!$B$3:$B$1850,">="&判定条件!$C$10,時間ごとの判定!$B$3:$B$1850,"<="&判定条件!$C$11,時間ごとの判定!$AN$3:$AN$1850,"利用可") -> 9 | I4: =IF(H4>=判定条件!$C$12,"利用可","不可") -> 利用可 | J4: =COUNTIFS(時間ごとの判定!$A$3:$A$1850,$A4,時間ごとの判定!$B$3:$B$1850,">="&判定条件!$C$10,時間ごとの判定!$B$3:$B$1850,"<="&判定条件!$C$11,時間ごとの判定!$AQ$3:$AQ$1850,"利用可") -> 9 | K4: =IF(J4>=判定条件!$C$12,"利用可","不可") -> 利用可 | L4: =COUNTIFS(時間ごとの判定!$A$3:$A$1850,$A4,時間ごとの判定!$B$3:$B$1850,">="&判定条件!$C$10,時間ごとの判定!$B$3:$B$1850,"<="&判定条件!$C$11,時間ごとの判定!$AT$3:$AT$1850,"利用可") -> 9 | M4: =IF(L4>=判定条件!$C$12,"利用可","不可") -> 利用可 | N4: =COUNTIFS(時間ごとの判定!$A$3:$A$1850,$A4,時間ごとの判定!$B$3:$B$1850,">="&判定条件!$C$10,時間ごとの判定!$B$3:$B$1850,"<="&判定条件!$C$11,時間ごとの判定!$AW$3:$AW$1850,"利用可") -> 9 | O4: =IF(N4>=判定条件!$C$12,"利用可","不可") -> 利用可 | P4: =IF(AND(E4="利用可",G4="利用可",I4="利用可"),"利用可","不可") -> 利用可 | Q4: =IF(AND(K4="利用可",M4="利用可",O4="利用可"),"利用可","不可") -> 利用可
A5: 46234 | B5: 金 | C5: 平日 | D5: =COUNTIFS(時間ごとの判定!$A$3:$A$1850,$A5,時間ごとの判定!$B$3:$B$1850,">="&判定条件!$C$10,時間ごとの判定!$B$3:$B$1850,"<="&判定条件!$C$11,時間ごとの判定!$AH$3:$AH$1850,"利用可") -> 8 | E5: =IF(D5>=判定条件!$C$12,"利用可","不可") -> 利用可 | F5: =COUNTIFS(時間ごとの判定!$A$3:$A$1850,$A5,時間ごとの判定!$B$3:$B$1850,">="&判定条件!$C$10,時間ごとの判定!$B$3:$B$1850,"<="&判定条件!$C$11,時間ごとの判定!$AK$3:$AK$1850,"利用可") -> 9 | G5: =IF(F5>=判定条件!$C$12,"利用可","不可") -> 利用可 | H5: =COUNTIFS(時間ごとの判定!$A$3:$A$1850,$A5,時間ごとの判定!$B$3:$B$1850,">="&判定条件!$C$10,時間ごとの判定!$B$3:$B$1850,"<="&判定条件!$C$11,時間ごとの判定!$AN$3:$AN$1850,"利用可") -> 9 | I5: =IF(H5>=判定条件!$C$12,"利用可","不可") -> 利用可 | J5: =COUNTIFS(時間ごとの判定!$A$3:$A$1850,$A5,時間ごとの判定!$B$3:$B$1850,">="&判定条件!$C$10,時間ごとの判定!$B$3:$B$1850,"<="&判定条件!$C$11,時間ごとの判定!$AQ$3:$AQ$1850,"利用可") -> 9 | K5: =IF(J5>=判定条件!$C$12,"利用可","不可") -> 利用可 | L5: =COUNTIFS(時間ごとの判定!$A$3:$A$1850,$A5,時間ごとの判定!$B$3:$B$1850,">="&判定条件!$C$10,時間ごとの判定!$B$3:$B$1850,"<="&判定条件!$C$11,時間ごとの判定!$AT$3:$AT$1850,"利用可") -> 9 | M5: =IF(L5>=判定条件!$C$12,"利用可","不可") -> 利用可 | N5: =COUNTIFS(時間ごとの判定!$A$3:$A$1850,$A5,時間ごとの判定!$B$3:$B$1850,">="&判定条件!$C$10,時間ごとの判定!$B$3:$B$1850,"<="&判定条件!$C$11,時間ごとの判定!$AW$3:$AW$1850,"利用可") -> 9 | O5: =IF(N5>=判定条件!$C$12,"利用可","不可") -> 利用可 | P5: =IF(AND(E5="利用可",G5="利用可",I5="利用可"),"利用可","不可") -> 利用可 | Q5: =IF(AND(K5="利用可",M5="利用可",O5="利用可"),"利用可","不可") -> 利用可
A6: 46235 | B6: 土 | C6: 土日 | D6: =COUNTIFS(時間ごとの判定!$A$3:$A$1850,$A6,時間ごとの判定!$B$3:$B$1850,">="&判定条件!$C$10,時間ごとの判定!$B$3:$B$1850,"<="&判定条件!$C$11,時間ごとの判定!$AH$3:$AH$1850,"利用可") -> 6 | E6: =IF(D6>=判定条件!$C$12,"利用可","不可") -> 不可 | F6: =COUNTIFS(時間ごとの判定!$A$3:$A$1850,$A6,時間ごとの判定!$B$3:$B$1850,">="&判定条件!$C$10,時間ごとの判定!$B$3:$B$1850,"<="&判定条件!$C$11,時間ごとの判定!$AK$3:$AK$1850,"利用可") -> 7 | G6: =IF(F6>=判定条件!$C$12,"利用可","不可") -> 利用可 | H6: =COUNTIFS(時間ごとの判定!$A$3:$A$1850,$A6,時間ごとの判定!$B$3:$B$1850,">="&判定条件!$C$10,時間ごとの判定!$B$3:$B$1850,"<="&判定条件!$C$11,時間ごとの判定!$AN$3:$AN$1850,"利用可") -> 7 | I6: =IF(H6>=判定条件!$C$12,"利用可","不可") -> 利用可 | J6: =COUNTIFS(時間ごとの判定!$A$3:$A$1850,$A6,時間ごとの判定!$B$3:$B$1850,">="&判定条件!$C$10,時間ごとの判定!$B$3:$B$1850,"<="&判定条件!$C$11,時間ごとの判定!$AQ$3:$AQ$1850,"利用可") -> 9 | K6: =IF(J6>=判定条件!$C$12,"利用可","不可") -> 利用可 | L6: =COUNTIFS(時間ごとの判定!$A$3:$A$1850,$A6,時間ごとの判定!$B$3:$B$1850,">="&判定条件!$C$10,時間ごとの判定!$B$3:$B$1850,"<="&判定条件!$C$11,時間ごとの判定!$AT$3:$AT$1850,"利用可") -> 9 | M6: =IF(L6>=判定条件!$C$12,"利用可","不可") -> 利用可 | N6: =COUNTIFS(時間ごとの判定!$A$3:$A$1850,$A6,時間ごとの判定!$B$3:$B$1850,">="&判定条件!$C$10,時間ごとの判定!$B$3:$B$1850,"<="&判定条件!$C$11,時間ごとの判定!$AW$3:$AW$1850,"利用可") -> 9 | O6: =IF(N6>=判定条件!$C$12,"利用可","不可") -> 利用可 | P6: =IF(AND(E6="利用可",G6="利用可",I6="利用可"),"利用可","不可") -> 不可 | Q6: =IF(AND(K6="利用可",M6="利用可",O6="利用可"),"利用可","不可") -> 利用可
A7: 46236 | B7: 日 | C7: 土日 | D7: =COUNTIFS(時間ごとの判定!$A$3:$A$1850,$A7,時間ごとの判定!$B$3:$B$1850,">="&判定条件!$C$10,時間ごとの判定!$B$3:$B$1850,"<="&判定条件!$C$11,時間ごとの判定!$AH$3:$AH$1850,"利用可") -> 9 | E7: =IF(D7>=判定条件!$C$12,"利用可","不可") -> 利用可 | F7: =COUNTIFS(時間ごとの判定!$A$3:$A$1850,$A7,時間ごとの判定!$B$3:$B$1850,">="&判定条件!$C$10,時間ごとの判定!$B$3:$B$1850,"<="&判定条件!$C$11,時間ごとの判定!$AK$3:$AK$1850,"利用可") -> 3 | G7: =IF(F7>=判定条件!$C$12,"利用可","不可") -> 不可 | H7: =COUNTIFS(時間ごとの判定!$A$3:$A$1850,$A7,時間ごとの判定!$B$3:$B$1850,">="&判定条件!$C$10,時間ごとの判定!$B$3:$B$1850,"<="&判定条件!$C$11,時間ごとの判定!$AN$3:$AN$1850,"利用可") -> 0 | I7: =IF(H7>=判定条件!$C$12,"利用可","不可") -> 不可 | J7: =COUNTIFS(時間ごとの判定!$A$3:$A$1850,$A7,時間ごとの判定!$B$3:$B$1850,">="&判定条件!$C$10,時間ごとの判定!$B$3:$B$1850,"<="&判定条件!$C$11,時間ごとの判定!$AQ$3:$AQ$1850,"利用可") -> 9 | K7: =IF(J7>=判定条件!$C$12,"利用可","不可") -> 利用可 | L7: =COUNTIFS(時間ごとの判定!$A$3:$A$1850,$A7,時間ごとの判定!$B$3:$B$1850,">="&判定条件!$C$10,時間ごとの判定!$B$3:$B$1850,"<="&判定条件!$C$11,時間ごとの判定!$AT$3:$AT$1850,"利用可") -> 9 | M7: =IF(L7>=判定条件!$C$12,"利用可","不可") -> 利用可 | N7: =COUNTIFS(時間ごとの判定!$A$3:$A$1850,$A7,時間ごとの判定!$B$3:$B$1850,">="&判定条件!$C$10,時間ごとの判定!$B$3:$B$1850,"<="&判定条件!$C$11,時間ごとの判定!$AW$3:$AW$1850,"利用可") -> 9 | O7: =IF(N7>=判定条件!$C$12,"利用可","不可") -> 利用可 | P7: =IF(AND(E7="利用可",G7="利用可",I7="利用可"),"利用可","不可") -> 不可 | Q7: =IF(AND(K7="利用可",M7="利用可",O7="利用可"),"利用可","不可") -> 利用可
A8: 46237 | B8: 月 | C8: 平日 | D8: =COUNTIFS(時間ごとの判定!$A$3:$A$1850,$A8,時間ごとの判定!$B$3:$B$1850,">="&判定条件!$C$10,時間ごとの判定!$B$3:$B$1850,"<="&判定条件!$C$11,時間ごとの判定!$AH$3:$AH$1850,"利用可") -> 9 | E8: =IF(D8>=判定条件!$C$12,"利用可","不可") -> 利用可 | F8: =COUNTIFS(時間ごとの判定!$A$3:$A$1850,$A8,時間ごとの判定!$B$3:$B$1850,">="&判定条件!$C$10,時間ごとの判定!$B$3:$B$1850,"<="&判定条件!$C$11,時間ごとの判定!$AK$3:$AK$1850,"利用可") -> 9 | G8: =IF(F8>=判定条件!$C$12,"利用可","不可") -> 利用可 | H8: =COUNTIFS(時間ごとの判定!$A$3:$A$1850,$A8,時間ごとの判定!$B$3:$B$1850,">="&判定条件!$C$10,時間ごとの判定!$B$3:$B$1850,"<="&判定条件!$C$11,時間ごとの判定!$AN$3:$AN$1850,"利用可") -> 9 | I8: =IF(H8>=判定条件!$C$12,"利用可","不可") -> 利用可 | J8: =COUNTIFS(時間ごとの判定!$A$3:$A$1850,$A8,時間ごとの判定!$B$3:$B$1850,">="&判定条件!$C$10,時間ごとの判定!$B$3:$B$1850,"<="&判定条件!$C$11,時間ごとの判定!$AQ$3:$AQ$1850,"利用可") -> 8 | K8: =IF(J8>=判定条件!$C$12,"利用可","不可") -> 利用可 | L8: =COUNTIFS(時間ごとの判定!$A$3:$A$1850,$A8,時間ごとの判定!$B$3:$B$1850,">="&判定条件!$C$10,時間ごとの判定!$B$3:$B$1850,"<="&判定条件!$C$11,時間ごとの判定!$AT$3:$AT$1850,"利用可") -> 9 | M8: =IF(L8>=判定条件!$C$12,"利用可","不可") -> 利用可 | N8: =COUNTIFS(時間ごとの判定!$A$3:$A$1850,$A8,時間ごとの判定!$B$3:$B$1850,">="&判定条件!$C$10,時間ごとの判定!$B$3:$B$1850,"<="&判定条件!$C$11,時間ごとの判定!$AW$3:$AW$1850,"利用可") -> 9 | O8: =IF(N8>=判定条件!$C$12,"利用可","不可") -> 利用可 | P8: =IF(AND(E8="利用可",G8="利用可",I8="利用可"),"利用可","不可") -> 利用可 | Q8: =IF(AND(K8="利用可",M8="利用可",O8="利用可"),"利用可","不可") -> 利用可
A9: 46238 | B9: 火 | C9: 平日 | D9: =COUNTIFS(時間ごとの判定!$A$3:$A$1850,$A9,時間ごとの判定!$B$3:$B$1850,">="&判定条件!$C$10,時間ごとの判定!$B$3:$B$1850,"<="&判定条件!$C$11,時間ごとの判定!$AH$3:$AH$1850,"利用可") -> 9 | E9: =IF(D9>=判定条件!$C$12,"利用可","不可") -> 利用可 | F9: =COUNTIFS(時間ごとの判定!$A$3:$A$1850,$A9,時間ごとの判定!$B$3:$B$1850,">="&判定条件!$C$10,時間ごとの判定!$B$3:$B$1850,"<="&判定条件!$C$11,時間ごとの判定!$AK$3:$AK$1850,"利用可") -> 9 | G9: =IF(F9>=判定条件!$C$12,"利用可","不可") -> 利用可 | H9: =COUNTIFS(時間ごとの判定!$A$3:$A$1850,$A9,時間ごとの判定!$B$3:$B$1850,">="&判定条件!$C$10,時間ごとの判定!$B$3:$B$1850,"<="&判定条件!$C$11,時間ごとの判定!$AN$3:$AN$1850,"利用可") -> 9 | I9: =IF(H9>=判定条件!$C$12,"利用可","不可") -> 利用可 | J9: =COUNTIFS(時間ごとの判定!$A$3:$A$1850,$A9,時間ごとの判定!$B$3:$B$1850,">="&判定条件!$C$10,時間ごとの判定!$B$3:$B$1850,"<="&判定条件!$C$11,時間ごとの判定!$AQ$3:$AQ$1850,"利用可") -> 9 | K9: =IF(J9>=判定条件!$C$12,"利用可","不可") -> 利用可 | L9: =COUNTIFS(時間ごとの判定!$A$3:$A$1850,$A9,時間ごとの判定!$B$3:$B$1850,">="&判定条件!$C$10,時間ごとの判定!$B$3:$B$1850,"<="&判定条件!$C$11,時間ごとの判定!$AT$3:$AT$1850,"利用可") -> 8 | M9: =IF(L9>=判定条件!$C$12,"利用可","不可") -> 利用可 | N9: =COUNTIFS(時間ごとの判定!$A$3:$A$1850,$A9,時間ごとの判定!$B$3:$B$1850,">="&判定条件!$C$10,時間ごとの判定!$B$3:$B$1850,"<="&判定条件!$C$11,時間ごとの判定!$AW$3:$AW$1850,"利用可") -> 9 | O9: =IF(N9>=判定条件!$C$12,"利用可","不可") -> 利用可 | P9: =IF(AND(E9="利用可",G9="利用可",I9="利用可"),"利用可","不可") -> 利用可 | Q9: =IF(AND(K9="利用可",M9="利用可",O9="利用可"),"利用可","不可") -> 利用可
A10: 46239 | B10: 水 | C10: 平日 | D10: =COUNTIFS(時間ごとの判定!$A$3:$A$1850,$A10,時間ごとの判定!$B$3:$B$1850,">="&判定条件!$C$10,時間ごとの判定!$B$3:$B$1850,"<="&判定条件!$C$11,時間ごとの判定!$AH$3:$AH$1850,"利用可") -> 9 | E10: =IF(D10>=判定条件!$C$12,"利用可","不可") -> 利用可 | F10: =COUNTIFS(時間ごとの判定!$A$3:$A$1850,$A10,時間ごとの判定!$B$3:$B$1850,">="&判定条件!$C$10,時間ごとの判定!$B$3:$B$1850,"<="&判定条件!$C$11,時間ごとの判定!$AK$3:$AK$1850,"利用可") -> 9 | G10: =IF(F10>=判定条件!$C$12,"利用可","不可") -> 利用可 | H10: =COUNTIFS(時間ごとの判定!$A$3:$A$1850,$A10,時間ごとの判定!$B$3:$B$1850,">="&判定条件!$C$10,時間ごとの判定!$B$3:$B$1850,"<="&判定条件!$C$11,時間ごとの判定!$AN$3:$AN$1850,"利用可") -> 9 | I10: =IF(H10>=判定条件!$C$12,"利用可","不可") -> 利用可 | J10: =COUNTIFS(時間ごとの判定!$A$3:$A$1850,$A10,時間ごとの判定!$B$3:$B$1850,">="&判定条件!$C$10,時間ごとの判定!$B$3:$B$1850,"<="&判定条件!$C$11,時間ごとの判定!$AQ$3:$AQ$1850,"利用可") -> 9 | K10: =IF(J10>=判定条件!$C$12,"利用可","不可") -> 利用可 | L10: =COUNTIFS(時間ごとの判定!$A$3:$A$1850,$A10,時間ごとの判定!$B$3:$B$1850,">="&判定条件!$C$10,時間ごとの判定!$B$3:$B$1850,"<="&判定条件!$C$11,時間ごとの判定!$AT$3:$AT$1850,"利用可") -> 9 | M10: =IF(L10>=判定条件!$C$12,"利用可","不可") -> 利用可 | N10: =COUNTIFS(時間ごとの判定!$A$3:$A$1850,$A10,時間ごとの判定!$B$3:$B$1850,">="&判定条件!$C$10,時間ごとの判定!$B$3:$B$1850,"<="&判定条件!$C$11,時間ごとの判定!$AW$3:$AW$1850,"利用可") -> 9 | O10: =IF(N10>=判定条件!$C$12,"利用可","不可") -> 利用可 | P10: =IF(AND(E10="利用可",G10="利用可",I10="利用可"),"利用可","不可") -> 利用可 | Q10: =IF(AND(K10="利用可",M10="利用可",O10="利用可"),"利用可","不可") -> 利用可
A11: 46240 | B11: 木 | C11: 平日 | D11: =COUNTIFS(時間ごとの判定!$A$3:$A$1850,$A11,時間ごとの判定!$B$3:$B$1850,">="&判定条件!$C$10,時間ごとの判定!$B$3:$B$1850,"<="&判定条件!$C$11,時間ごとの判定!$AH$3:$AH$1850,"利用可") -> 9 | E11: =IF(D11>=判定条件!$C$12,"利用可","不可") -> 利用可 | F11: =COUNTIFS(時間ごとの判定!$A$3:$A$1850,$A11,時間ごとの判定!$B$3:$B$1850,">="&判定条件!$C$10,時間ごとの判定!$B$3:$B$1850,"<="&判定条件!$C$11,時間ごとの判定!$AK$3:$AK$1850,"利用可") -> 9 | G11: =IF(F11>=判定条件!$C$12,"利用可","不可") -> 利用可 | H11: =COUNTIFS(時間ごとの判定!$A$3:$A$1850,$A11,時間ごとの判定!$B$3:$B$1850,">="&判定条件!$C$10,時間ごとの判定!$B$3:$B$1850,"<="&判定条件!$C$11,時間ごとの判定!$AN$3:$AN$1850,"利用可") -> 9 | I11: =IF(H11>=判定条件!$C$12,"利用可","不可") -> 利用可 | J11: =COUNTIFS(時間ごとの判定!$A$3:$A$1850,$A11,時間ごとの判定!$B$3:$B$1850,">="&判定条件!$C$10,時間ごとの判定!$B$3:$B$1850,"<="&判定条件!$C$11,時間ごとの判定!$AQ$3:$AQ$1850,"利用可") -> 9 | K11: =IF(J11>=判定条件!$C$12,"利用可","不可") -> 利用可 | L11: =COUNTIFS(時間ごとの判定!$A$3:$A$1850,$A11,時間ごとの判定!$B$3:$B$1850,">="&判定条件!$C$10,時間ごとの判定!$B$3:$B$1850,"<="&判定条件!$C$11,時間ごとの判定!$AT$3:$AT$1850,"利用可") -> 9 | M11: =IF(L11>=判定条件!$C$12,"利用可","不可") -> 利用可 | N11: =COUNTIFS(時間ごとの判定!$A$3:$A$1850,$A11,時間ごとの判定!$B$3:$B$1850,">="&判定条件!$C$10,時間ごとの判定!$B$3:$B$1850,"<="&判定条件!$C$11,時間ごとの判定!$AW$3:$AW$1850,"利用可") -> 9 | O11: =IF(N11>=判定条件!$C$12,"利用可","不可") -> 利用可 | P11: =IF(AND(E11="利用可",G11="利用可",I11="利用可"),"利用可","不可") -> 利用可 | Q11: =IF(AND(K11="利用可",M11="利用可",O11="利用可"),"利用可","不可") -> 利用可
A12: 46241 | B12: 金 | C12: 平日 | D12: =COUNTIFS(時間ごとの判定!$A$3:$A$1850,$A12,時間ごとの判定!$B$3:$B$1850,">="&判定条件!$C$10,時間ごとの判定!$B$3:$B$1850,"<="&判定条件!$C$11,時間ごとの判定!$AH$3:$AH$1850,"利用可") -> 9 | E12: =IF(D12>=判定条件!$C$12,"利用可","不可") -> 利用可 | F12: =COUNTIFS(時間ごとの判定!$A$3:$A$1850,$A12,時間ごとの判定!$B$3:$B$1850,">="&判定条件!$C$10,時間ごとの判定!$B$3:$B$1850,"<="&判定条件!$C$11,時間ごとの判定!$AK$3:$AK$1850,"利用可") -> 9 | G12: =IF(F12>=判定条件!$C$12,"利用可","不可") -> 利用可 | H12: =COUNTIFS(時間ごとの判定!$A$3:$A$1850,$A12,時間ごとの判定!$B$3:$B$1850,">="&判定条件!$C$10,時間ごとの判定!$B$3:$B$1850,"<="&判定条件!$C$11,時間ごとの判定!$AN$3:$AN$1850,"利用可") -> 9 | I12: =IF(H12>=判定条件!$C$12,"利用可","不可") -> 利用可 | J12: =COUNTIFS(時間ごとの判定!$A$3:$A$1850,$A12,時間ごとの判定!$B$3:$B$1850,">="&判定条件!$C$10,時間ごとの判定!$B$3:$B$1850,"<="&判定条件!$C$11,時間ごとの判定!$AQ$3:$AQ$1850,"利用可") -> 9 | K12: =IF(J12>=判定条件!$C$12,"利用可","不可") -> 利用可 | L12: =COUNTIFS(時間ごとの判定!$A$3:$A$1850,$A12,時間ごとの判定!$B$3:$B$1850,">="&判定条件!$C$10,時間ごとの判定!$B$3:$B$1850,"<="&判定条件!$C$11,時間ごとの判定!$AT$3:$AT$1850,"利用可") -> 9 | M12: =IF(L12>=判定条件!$C$12,"利用可","不可") -> 利用可 | N12: =COUNTIFS(時間ごとの判定!$A$3:$A$1850,$A12,時間ごとの判定!$B$3:$B$1850,">="&判定条件!$C$10,時間ごとの判定!$B$3:$B$1850,"<="&判定条件!$C$11,時間ごとの判定!$AW$3:$AW$1850,"利用可") -> 9 | O12: =IF(N12>=判定条件!$C$12,"利用可","不可") -> 利用可 | P12: =IF(AND(E12="利用可",G12="利用可",I12="利用可"),"利用可","不可") -> 利用可 | Q12: =IF(AND(K12="利用可",M12="利用可",O12="利用可"),"利用可","不可") -> 利用可
A13: 46242 | B13: 土 | C13: 土日 | D13: =COUNTIFS(時間ごとの判定!$A$3:$A$1850,$A13,時間ごとの判定!$B$3:$B$1850,">="&判定条件!$C$10,時間ごとの判定!$B$3:$B$1850,"<="&判定条件!$C$11,時間ごとの判定!$AH$3:$AH$1850,"利用可") -> 9 | E13: =IF(D13>=判定条件!$C$12,"利用可","不可") -> 利用可 | F13: =COUNTIFS(時間ごとの判定!$A$3:$A$1850,$A13,時間ごとの判定!$B$3:$B$1850,">="&判定条件!$C$10,時間ごとの判定!$B$3:$B$1850,"<="&判定条件!$C$11,時間ごとの判定!$AK$3:$AK$1850,"利用可") -> 0 | G13: =IF(F13>=判定条件!$C$12,"利用可","不可") -> 不可 | H13: =COUNTIFS(時間ごとの判定!$A$3:$A$1850,$A13,時間ごとの判定!$B$3:$B$1850,">="&判定条件!$C$10,時間ごとの判定!$B$3:$B$1850,"<="&判定条件!$C$11,時間ごとの判定!$AN$3:$AN$1850,"利用可") -> 5 | I13: =IF(H13>=判定条件!$C$12,"利用可","不可") -> 不可 | J13: =COUNTIFS(時間ごとの判定!$A$3:$A$1850,$A13,時間ごとの判定!$B$3:$B$1850,">="&判定条件!$C$10,時間ごとの判定!$B$3:$B$1850,"<="&判定条件!$C$11,時間ごとの判定!$AQ$3:$AQ$1850,"利用可") -> 8 | K13: =IF(J13>=判定条件!$C$12,"利用可","不可") -> 利用可 | L13: =COUNTIFS(時間ごとの判定!$A$3:$A$1850,$A13,時間ごとの判定!$B$3:$B$1850,">="&判定条件!$C$10,時間ごとの判定!$B$3:$B$1850,"<="&判定条件!$C$11,時間ごとの判定!$AT$3:$AT$1850,"利用可") -> 9 | M13: =IF(L13>=判定条件!$C$12,"利用可","不可") -> 利用可 | N13: =COUNTIFS(時間ごとの判定!$A$3:$A$1850,$A13,時間ごとの判定!$B$3:$B$1850,">="&判定条件!$C$10,時間ごとの判定!$B$3:$B$1850,"<="&判定条件!$C$11,時間ごとの判定!$AW$3:$AW$1850,"利用可") -> 9 | O13: =IF(N13>=判定条件!$C$12,"利用可","不可") -> 利用可 | P13: =IF(AND(E13="利用可",G13="利用可",I13="利用可"),"利用可","不可") -> 不可 | Q13: =IF(AND(K13="利用可",M13="利用可",O13="利用可"),"利用可","不可") -> 利用可
A14: 46243 | B14: 日 | C14: 土日 | D14: =COUNTIFS(時間ごとの判定!$A$3:$A$1850,$A14,時間ごとの判定!$B$3:$B$1850,">="&判定条件!$C$10,時間ごとの判定!$B$3:$B$1850,"<="&判定条件!$C$11,時間ごとの判定!$AH$3:$AH$1850,"利用可") -> 9 | E14: =IF(D14>=判定条件!$C$12,"利用可","不可") -> 利用可 | F14: =COUNTIFS(時間ごとの判定!$A$3:$A$1850,$A14,時間ごとの判定!$B$3:$B$1850,">="&判定条件!$C$10,時間ごとの判定!$B$3:$B$1850,"<="&判定条件!$C$11,時間ごとの判定!$AK$3:$AK$1850,"利用可") -> 0 | G14: =IF(F14>=判定条件!$C$12,"利用可","不可") -> 不可 | H14: =COUNTIFS(時間ごとの判定!$A$3:$A$1850,$A14,時間ごとの判定!$B$3:$B$1850,">="&判定条件!$C$10,時間ごとの判定!$B$3:$B$1850,"<="&判定条件!$C$11,時間ごとの判定!$AN$3:$AN$1850,"利用可") -> 0 | I14: =IF(H14>=判定条件!$C$12,"利用可","不可") -> 不可 | J14: =COUNTIFS(時間ごとの判定!$A$3:$A$1850,$A14,時間ごとの判定!$B$3:$B$1850,">="&判定条件!$C$10,時間ごとの判定!$B$3:$B$1850,"<="&判定条件!$C$11,時間ごとの判定!$AQ$3:$AQ$1850,"利用可") -> 8 | K14: =IF(J14>=判定条件!$C$12,"利用可","不可") -> 利用可 | L14: =COUNTIFS(時間ごとの判定!$A$3:$A$1850,$A14,時間ごとの判定!$B$3:$B$1850,">="&判定条件!$C$10,時間ごとの判定!$B$3:$B$1850,"<="&判定条件!$C$11,時間ごとの判定!$AT$3:$AT$1850,"利用可") -> 9 | M14: =IF(L14>=判定条件!$C$12,"利用可","不可") -> 利用可 | N14: =COUNTIFS(時間ごとの判定!$A$3:$A$1850,$A14,時間ごとの判定!$B$3:$B$1850,">="&判定条件!$C$10,時間ごとの判定!$B$3:$B$1850,"<="&判定条件!$C$11,時間ごとの判定!$AW$3:$AW$1850,"利用可") -> 9 | O14: =IF(N14>=判定条件!$C$12,"利用可","不可") -> 利用可 | P14: =IF(AND(E14="利用可",G14="利用可",I14="利用可"),"利用可","不可") -> 不可 | Q14: =IF(AND(K14="利用可",M14="利用可",O14="利用可"),"利用可","不可") -> 利用可
A15: 46244 | B15: 月 | C15: 平日 | D15: =COUNTIFS(時間ごとの判定!$A$3:$A$1850,$A15,時間ごとの判定!$B$3:$B$1850,">="&判定条件!$C$10,時間ごとの判定!$B$3:$B$1850,"<="&判定条件!$C$11,時間ごとの判定!$AH$3:$AH$1850,"利用可") -> 9 | E15: =IF(D15>=判定条件!$C$12,"利用可","不可") -> 利用可 | F15: =COUNTIFS(時間ごとの判定!$A$3:$A$1850,$A15,時間ごとの判定!$B$3:$B$1850,">="&判定条件!$C$10,時間ごとの判定!$B$3:$B$1850,"<="&判定条件!$C$11,時間ごとの判定!$AK$3:$AK$1850,"利用可") -> 0 | G15: =IF(F15>=判定条件!$C$12,"利用可","不可") -> 不可 | H15: =COUNTIFS(時間ごとの判定!$A$3:$A$1850,$A15,時間ごとの判定!$B$3:$B$1850,">="&判定条件!$C$10,時間ごとの判定!$B$3:$B$1850,"<="&判定条件!$C$11,時間ごとの判定!$AN$3:$AN$1850,"利用可") -> 9 | I15: =IF(H15>=判定条件!$C$12,"利用可","不可") -> 利用可 | J15: =COUNTIFS(時間ごとの判定!$A$3:$A$1850,$A15,時間ごとの判定!$B$3:$B$1850,">="&判定条件!$C$10,時間ごとの判定!$B$3:$B$1850,"<="&判定条件!$C$11,時間ごとの判定!$AQ$3:$AQ$1850,"利用可") -> 9 | K15: =IF(J15>=判定条件!$C$12,"利用可","不可") -> 利用可 | L15: =COUNTIFS(時間ごとの判定!$A$3:$A$1850,$A15,時間ごとの判定!$B$3:$B$1850,">="&判定条件!$C$10,時間ごとの判定!$B$3:$B$1850,"<="&判定条件!$C$11,時間ごとの判定!$AT$3:$AT$1850,"利用可") -> 8 | M15: =IF(L15>=判定条件!$C$12,"利用可","不可") -> 利用可 | N15: =COUNTIFS(時間ごとの判定!$A$3:$A$1850,$A15,時間ごとの判定!$B$3:$B$1850,">="&判定条件!$C$10,時間ごとの判定!$B$3:$B$1850,"<="&判定条件!$C$11,時間ごとの判定!$AW$3:$AW$1850,"利用可") -> 9 | O15: =IF(N15>=判定条件!$C$12,"利用可","不可") -> 利用可 | P15: =IF(AND(E15="利用可",G15="利用可",I15="利用可"),"利用可","不可") -> 不可 | Q15: =IF(AND(K15="利用可",M15="利用可",O15="利用可"),"利用可","不可") -> 利用可
... A18: 46247 | B18: 木 | C18: 平日 | D18: =COUNTIFS(時間ごとの判定!$A$3:$A$1850,$A18,時間ごとの判定!$B$3:$B$1850,">="&判定条件!$C$10,時間ごとの判定!$B$3:$B$1850,"<="&判定条件!$C$11,時間ごとの判定!$AH$3:$AH$1850,"利用可") -> 7 | E18: =IF(D18>=判定条件!$C$12,"利用可","不可") -> 利用可 | F18: =COUNTIFS(時間ごとの判定!$A$3:$A$1850,$A18,時間ごとの判定!$B$3:$B$1850,">="&判定条件!$C$10,時間ごとの判定!$B$3:$B$1850,"<="&判定条件!$C$11,時間ごとの判定!$AK$3:$AK$1850,"利用可") -> 0 | G18: =IF(F18>=判定条件!$C$12,"利用可","不可") -> 不可 | H18: =COUNTIFS(時間ごとの判定!$A$3:$A$1850,$A18,時間ごとの判定!$B$3:$B$1850,">="&判定条件!$C$10,時間ごとの判定!$B$3:$B$1850,"<="&判定条件!$C$11,時間ごとの判定!$AN$3:$AN$1850,"利用可") -> 9 | I18: =IF(H18>=判定条件!$C$12,"利用可","不可") -> 利用可 | J18: =COUNTIFS(時間ごとの判定!$A$3:$A$1850,$A18,時間ごとの判定!$B$3:$B$1850,">="&判定条件!$C$10,時間ごとの判定!$B$3:$B$1850,"<="&判定条件!$C$11,時間ごとの判定!$AQ$3:$AQ$1850,"利用可") -> 8 | K18: =IF(J18>=判定条件!$C$12,"利用可","不可") -> 利用可 | L18: =COUNTIFS(時間ごとの判定!$A$3:$A$1850,$A18,時間ごとの判定!$B$3:$B$1850,">="&判定条件!$C$10,時間ごとの判定!$B$3:$B$1850,"<="&判定条件!$C$11,時間ごとの判定!$AT$3:$AT$1850,"利用可") -> 7 | M18: =IF(L18>=判定条件!$C$12,"利用可","不可") -> 利用可 | N18: =COUNTIFS(時間ごとの判定!$A$3:$A$1850,$A18,時間ごとの判定!$B$3:$B$1850,">="&判定条件!$C$10,時間ごとの判定!$B$3:$B$1850,"<="&判定条件!$C$11,時間ごとの判定!$AW$3:$AW$1850,"利用可") -> 9 | O18: =IF(N18>=判定条件!$C$12,"利用可","不可") -> 利用可 | P18: =IF(AND(E18="利用可",G18="利用可",I18="利用可"),"利用可","不可") -> 不可 | Q18: =IF(AND(K18="利用可",M18="利用可",O18="利用可"),"利用可","不可") -> 利用可
A19: 46248 | B19: 金 | C19: 平日 | D19: =COUNTIFS(時間ごとの判定!$A$3:$A$1850,$A19,時間ごとの判定!$B$3:$B$1850,">="&判定条件!$C$10,時間ごとの判定!$B$3:$B$1850,"<="&判定条件!$C$11,時間ごとの判定!$AH$3:$AH$1850,"利用可") -> 8 | E19: =IF(D19>=判定条件!$C$12,"利用可","不可") -> 利用可 | F19: =COUNTIFS(時間ごとの判定!$A$3:$A$1850,$A19,時間ごとの判定!$B$3:$B$1850,">="&判定条件!$C$10,時間ごとの判定!$B$3:$B$1850,"<="&判定条件!$C$11,時間ごとの判定!$AK$3:$AK$1850,"利用可") -> 1 | G19: =IF(F19>=判定条件!$C$12,"利用可","不可") -> 不可 | H19: =COUNTIFS(時間ごとの判定!$A$3:$A$1850,$A19,時間ごとの判定!$B$3:$B$1850,">="&判定条件!$C$10,時間ごとの判定!$B$3:$B$1850,"<="&判定条件!$C$11,時間ごとの判定!$AN$3:$AN$1850,"利用可") -> 7 | I19: =IF(H19>=判定条件!$C$12,"利用可","不可") -> 利用可 | J19: =COUNTIFS(時間ごとの判定!$A$3:$A$1850,$A19,時間ごとの判定!$B$3:$B$1850,">="&判定条件!$C$10,時間ごとの判定!$B$3:$B$1850,"<="&判定条件!$C$11,時間ごとの判定!$AQ$3:$AQ$1850,"利用可") -> 7 | K19: =IF(J19>=判定条件!$C$12,"利用可","不可") -> 利用可 | L19: =COUNTIFS(時間ごとの判定!$A$3:$A$1850,$A19,時間ごとの判定!$B$3:$B$1850,">="&判定条件!$C$10,時間ごとの判定!$B$3:$B$1850,"<="&判定条件!$C$11,時間ごとの判定!$AT$3:$AT$1850,"利用可") -> 7 | M19: =IF(L19>=判定条件!$C$12,"利用可","不可") -> 利用可 | N19: =COUNTIFS(時間ごとの判定!$A$3:$A$1850,$A19,時間ごとの判定!$B$3:$B$1850,">="&判定条件!$C$10,時間ごとの判定!$B$3:$B$1850,"<="&判定条件!$C$11,時間ごとの判定!$AW$3:$AW$1850,"利用可") -> 8 | O19: =IF(N19>=判定条件!$C$12,"利用可","不可") -> 利用可 | P19: =IF(AND(E19="利用可",G19="利用可",I19="利用可"),"利用可","不可") -> 不可 | Q19: =IF(AND(K19="利用可",M19="利用可",O19="利用可"),"利用可","不可") -> 利用可 | R19: 8-2の排気・吸気温度が欠け（判定不能）
A20: 46249 | B20: 土 | C20: 土日 | D20: =COUNTIFS(時間ごとの判定!$A$3:$A$1850,$A20,時間ごとの判定!$B$3:$B$1850,">="&判定条件!$C$10,時間ごとの判定!$B$3:$B$1850,"<="&判定条件!$C$11,時間ごとの判定!$AH$3:$AH$1850,"利用可") -> 4 | E20: =IF(D20>=判定条件!$C$12,"利用可","不可") -> 不可 | F20: =COUNTIFS(時間ごとの判定!$A$3:$A$1850,$A20,時間ごとの判定!$B$3:$B$1850,">="&判定条件!$C$10,時間ごとの判定!$B$3:$B$1850,"<="&判定条件!$C$11,時間ごとの判定!$AK$3:$AK$1850,"利用可") -> 0 | G20: =IF(F20>=判定条件!$C$12,"利用可","不可") -> 不可 | H20: =COUNTIFS(時間ごとの判定!$A$3:$A$1850,$A20,時間ごとの判定!$B$3:$B$1850,">="&判定条件!$C$10,時間ごとの判定!$B$3:$B$1850,"<="&判定条件!$C$11,時間ごとの判定!$AN$3:$AN$1850,"利用可") -> 0 | I20: =IF(H20>=判定条件!$C$12,"利用可","不可") -> 不可 | J20: =COUNTIFS(時間ごとの判定!$A$3:$A$1850,$A20,時間ごとの判定!$B$3:$B$1850,">="&判定条件!$C$10,時間ごとの判定!$B$3:$B$1850,"<="&判定条件!$C$11,時間ごとの判定!$AQ$3:$AQ$1850,"利用可") -> 9 | K20: =IF(J20>=判定条件!$C$12,"利用可","不可") -> 利用可 | L20: =COUNTIFS(時間ごとの判定!$A$3:$A$1850,$A20,時間ごとの判定!$B$3:$B$1850,">="&判定条件!$C$10,時間ごとの判定!$B$3:$B$1850,"<="&判定条件!$C$11,時間ごとの判定!$AT$3:$AT$1850,"利用可") -> 4 | M20: =IF(L20>=判定条件!$C$12,"利用可","不可") -> 不可 | N20: =COUNTIFS(時間ごとの判定!$A$3:$A$1850,$A20,時間ごとの判定!$B$3:$B$1850,">="&判定条件!$C$10,時間ごとの判定!$B$3:$B$1850,"<="&判定条件!$C$11,時間ごとの判定!$AW$3:$AW$1850,"利用可") -> 9 | O20: =IF(N20>=判定条件!$C$12,"利用可","不可") -> 利用可 | P20: =IF(AND(E20="利用可",G20="利用可",I20="利用可"),"利用可","不可") -> 不可 | Q20: =IF(AND(K20="利用可",M20="利用可",O20="利用可"),"利用可","不可") -> 不可 | R20: 8-2の排気・吸気温度が欠け（判定不能）
A21: 46250 | B21: 日 | C21: 土日 | D21: =COUNTIFS(時間ごとの判定!$A$3:$A$1850,$A21,時間ごとの判定!$B$3:$B$1850,">="&判定条件!$C$10,時間ごとの判定!$B$3:$B$1850,"<="&判定条件!$C$11,時間ごとの判定!$AH$3:$AH$1850,"利用可") -> 0 | E21: =IF(D21>=判定条件!$C$12,"利用可","不可") -> 不可 | F21: =COUNTIFS(時間ごとの判定!$A$3:$A$1850,$A21,時間ごとの判定!$B$3:$B$1850,">="&判定条件!$C$10,時間ごとの判定!$B$3:$B$1850,"<="&判定条件!$C$11,時間ごとの判定!$AK$3:$AK$1850,"利用可") -> 0 | G21: =IF(F21>=判定条件!$C$12,"利用可","不可") -> 不可 | H21: =COUNTIFS(時間ごとの判定!$A$3:$A$1850,$A21,時間ごとの判定!$B$3:$B$1850,">="&判定条件!$C$10,時間ごとの判定!$B$3:$B$1850,"<="&判定条件!$C$11,時間ごとの判定!$AN$3:$AN$1850,"利用可") -> 1 | I21: =IF(H21>=判定条件!$C$12,"利用可","不可") -> 不可 | J21: =COUNTIFS(時間ごとの判定!$A$3:$A$1850,$A21,時間ごとの判定!$B$3:$B$1850,">="&判定条件!$C$10,時間ごとの判定!$B$3:$B$1850,"<="&判定条件!$C$11,時間ごとの判定!$AQ$3:$AQ$1850,"利用可") -> 9 | K21: =IF(J21>=判定条件!$C$12,"利用可","不可") -> 利用可 | L21: =COUNTIFS(時間ごとの判定!$A$3:$A$1850,$A21,時間ごとの判定!$B$3:$B$1850,">="&判定条件!$C$10,時間ごとの判定!$B$3:$B$1850,"<="&判定条件!$C$11,時間ごとの判定!$AT$3:$AT$1850,"利用可") -> 4 | M21: =IF(L21>=判定条件!$C$12,"利用可","不可") -> 不可 | N21: =COUNTIFS(時間ごとの判定!$A$3:$A$1850,$A21,時間ごとの判定!$B$3:$B$1850,">="&判定条件!$C$10,時間ごとの判定!$B$3:$B$1850,"<="&判定条件!$C$11,時間ごとの判定!$AW$3:$AW$1850,"利用可") -> 9 | O21: =IF(N21>=判定条件!$C$12,"利用可","不可") -> 利用可 | P21: =IF(AND(E21="利用可",G21="利用可",I21="利用可"),"利用可","不可") -> 不可 | Q21: =IF(AND(K21="利用可",M21="利用可",O21="利用可"),"利用可","不可") -> 不可 | R21: 8-2の排気・吸気温度が欠け（判定不能）
A22: 46251 | B22: 月 | C22: 平日 | D22: =COUNTIFS(時間ごとの判定!$A$3:$A$1850,$A22,時間ごとの判定!$B$3:$B$1850,">="&判定条件!$C$10,時間ごとの判定!$B$3:$B$1850,"<="&判定条件!$C$11,時間ごとの判定!$AH$3:$AH$1850,"利用可") -> 9 | E22: =IF(D22>=判定条件!$C$12,"利用可","不可") -> 利用可 | F22: =COUNTIFS(時間ごとの判定!$A$3:$A$1850,$A22,時間ごとの判定!$B$3:$B$1850,">="&判定条件!$C$10,時間ごとの判定!$B$3:$B$1850,"<="&判定条件!$C$11,時間ごとの判定!$AK$3:$AK$1850,"利用可") -> 0 | G22: =IF(F22>=判定条件!$C$12,"利用可","不可") -> 不可 | H22: =COUNTIFS(時間ごとの判定!$A$3:$A$1850,$A22,時間ごとの判定!$B$3:$B$1850,">="&判定条件!$C$10,時間ごとの判定!$B$3:$B$1850,"<="&判定条件!$C$11,時間ごとの判定!$AN$3:$AN$1850,"利用可") -> 9 | I22: =IF(H22>=判定条件!$C$12,"利用可","不可") -> 利用可 | J22: =COUNTIFS(時間ごとの判定!$A$3:$A$1850,$A22,時間ごとの判定!$B$3:$B$1850,">="&判定条件!$C$10,時間ごとの判定!$B$3:$B$1850,"<="&判定条件!$C$11,時間ごとの判定!$AQ$3:$AQ$1850,"利用可") -> 9 | K22: =IF(J22>=判定条件!$C$12,"利用可","不可") -> 利用可 | L22: =COUNTIFS(時間ごとの判定!$A$3:$A$1850,$A22,時間ごとの判定!$B$3:$B$1850,">="&判定条件!$C$10,時間ごとの判定!$B$3:$B$1850,"<="&判定条件!$C$11,時間ごとの判定!$AT$3:$AT$1850,"利用可") -> 8 | M22: =IF(L22>=判定条件!$C$12,"利用可","不可") -> 利用可 | N22: =COUNTIFS(時間ごとの判定!$A$3:$A$1850,$A22,時間ごとの判定!$B$3:$B$1850,">="&判定条件!$C$10,時間ごとの判定!$B$3:$B$1850,"<="&判定条件!$C$11,時間ごとの判定!$AW$3:$AW$1850,"利用可") -> 9 | O22: =IF(N22>=判定条件!$C$12,"利用可","不可") -> 利用可 | P22: =IF(AND(E22="利用可",G22="利用可",I22="利用可"),"利用可","不可") -> 不可 | Q22: =IF(AND(K22="利用可",M22="利用可",O22="利用可"),"利用可","不可") -> 利用可 | R22: 8-2の排気・吸気温度が欠け（判定不能）
A23: 46252 | B23: 火 | C23: 平日 | D23: =COUNTIFS(時間ごとの判定!$A$3:$A$1850,$A23,時間ごとの判定!$B$3:$B$1850,">="&判定条件!$C$10,時間ごとの判定!$B$3:$B$1850,"<="&判定条件!$C$11,時間ごとの判定!$AH$3:$AH$1850,"利用可") -> 9 | E23: =IF(D23>=判定条件!$C$12,"利用可","不可") -> 利用可 | F23: =COUNTIFS(時間ごとの判定!$A$3:$A$1850,$A23,時間ごとの判定!$B$3:$B$1850,">="&判定条件!$C$10,時間ごとの判定!$B$3:$B$1850,"<="&判定条件!$C$11,時間ごとの判定!$AK$3:$AK$1850,"利用可") -> 0 | G23: =IF(F23>=判定条件!$C$12,"利用可","不可") -> 不可 | H23: =COUNTIFS(時間ごとの判定!$A$3:$A$1850,$A23,時間ごとの判定!$B$3:$B$1850,">="&判定条件!$C$10,時間ごとの判定!$B$3:$B$1850,"<="&判定条件!$C$11,時間ごとの判定!$AN$3:$AN$1850,"利用可") -> 9 | I23: =IF(H23>=判定条件!$C$12,"利用可","不可") -> 利用可 | J23: =COUNTIFS(時間ごとの判定!$A$3:$A$1850,$A23,時間ごとの判定!$B$3:$B$1850,">="&判定条件!$C$10,時間ごとの判定!$B$3:$B$1850,"<="&判定条件!$C$11,時間ごとの判定!$AQ$3:$AQ$1850,"利用可") -> 9 | K23: =IF(J23>=判定条件!$C$12,"利用可","不可") -> 利用可 | L23: =COUNTIFS(時間ごとの判定!$A$3:$A$1850,$A23,時間ごとの判定!$B$3:$B$1850,">="&判定条件!$C$10,時間ごとの判定!$B$3:$B$1850,"<="&判定条件!$C$11,時間ごとの判定!$AT$3:$AT$1850,"利用可") -> 9 | M23: =IF(L23>=判定条件!$C$12,"利用可","不可") -> 利用可 | N23: =COUNTIFS(時間ごとの判定!$A$3:$A$1850,$A23,時間ごとの判定!$B$3:$B$1850,">="&判定条件!$C$10,時間ごとの判定!$B$3:$B$1850,"<="&判定条件!$C$11,時間ごとの判定!$AW$3:$AW$1850,"利用可") -> 9 | O23: =IF(N23>=判定条件!$C$12,"利用可","不可") -> 利用可 | P23: =IF(AND(E23="利用可",G23="利用可",I23="利用可"),"利用可","不可") -> 不可 | Q23: =IF(AND(K23="利用可",M23="利用可",O23="利用可"),"利用可","不可") -> 利用可 | R23: 8-2の排気・吸気温度が欠け（判定不能）
A24: 46253 | B24: 水 | C24: 平日 | D24: =COUNTIFS(時間ごとの判定!$A$3:$A$1850,$A24,時間ごとの判定!$B$3:$B$1850,">="&判定条件!$C$10,時間ごとの判定!$B$3:$B$1850,"<="&判定条件!$C$11,時間ごとの判定!$AH$3:$AH$1850,"利用可") -> 9 | E24: =IF(D24>=判定条件!$C$12,"利用可","不可") -> 利用可 | F24: =COUNTIFS(時間ごとの判定!$A$3:$A$1850,$A24,時間ごとの判定!$B$3:$B$1850,">="&判定条件!$C$10,時間ごとの判定!$B$3:$B$1850,"<="&判定条件!$C$11,時間ごとの判定!$AK$3:$AK$1850,"利用可") -> 0 | G24: =IF(F24>=判定条件!$C$12,"利用可","不可") -> 不可 | H24: =COUNTIFS(時間ごとの判定!$A$3:$A$1850,$A24,時間ごとの判定!$B$3:$B$1850,">="&判定条件!$C$10,時間ごとの判定!$B$3:$B$1850,"<="&判定条件!$C$11,時間ごとの判定!$AN$3:$AN$1850,"利用可") -> 8 | I24: =IF(H24>=判定条件!$C$12,"利用可","不可") -> 利用可 | J24: =COUNTIFS(時間ごとの判定!$A$3:$A$1850,$A24,時間ごとの判定!$B$3:$B$1850,">="&判定条件!$C$10,時間ごとの判定!$B$3:$B$1850,"<="&判定条件!$C$11,時間ごとの判定!$AQ$3:$AQ$1850,"利用可") -> 9 | K24: =IF(J24>=判定条件!$C$12,"利用可","不可") -> 利用可 | L24: =COUNTIFS(時間ごとの判定!$A$3:$A$1850,$A24,時間ごとの判定!$B$3:$B$1850,">="&判定条件!$C$10,時間ごとの判定!$B$3:$B$1850,"<="&判定条件!$C$11,時間ごとの判定!$AT$3:$AT$1850,"利用可") -> 8 | M24: =IF(L24>=判定条件!$C$12,"利用可","不可") -> 利用可 | N24: =COUNTIFS(時間ごとの判定!$A$3:$A$1850,$A24,時間ごとの判定!$B$3:$B$1850,">="&判定条件!$C$10,時間ごとの判定!$B$3:$B$1850,"<="&判定条件!$C$11,時間ごとの判定!$AW$3:$AW$1850,"利用可") -> 9 | O24: =IF(N24>=判定条件!$C$12,"利用可","不可") -> 利用可 | P24: =IF(AND(E24="利用可",G24="利用可",I24="利用可"),"利用可","不可") -> 不可 | Q24: =IF(AND(K24="利用可",M24="利用可",O24="利用可"),"利用可","不可") -> 利用可 | R24: 8-2の排気・吸気温度が欠け（判定不能）
A25: 46254 | B25: 木 | C25: 平日 | D25: =COUNTIFS(時間ごとの判定!$A$3:$A$1850,$A25,時間ごとの判定!$B$3:$B$1850,">="&判定条件!$C$10,時間ごとの判定!$B$3:$B$1850,"<="&判定条件!$C$11,時間ごとの判定!$AH$3:$AH$1850,"利用可") -> 9 | E25: =IF(D25>=判定条件!$C$12,"利用可","不可") -> 利用可 | F25: =COUNTIFS(時間ごとの判定!$A$3:$A$1850,$A25,時間ごとの判定!$B$3:$B$1850,">="&判定条件!$C$10,時間ごとの判定!$B$3:$B$1850,"<="&判定条件!$C$11,時間ごとの判定!$AK$3:$AK$1850,"利用可") -> 0 | G25: =IF(F25>=判定条件!$C$12,"利用可","不可") -> 不可 | H25: =COUNTIFS(時間ごとの判定!$A$3:$A$1850,$A25,時間ごとの判定!$B$3:$B$1850,">="&判定条件!$C$10,時間ごとの判定!$B$3:$B$1850,"<="&判定条件!$C$11,時間ごとの判定!$AN$3:$AN$1850,"利用可") -> 9 | I25: =IF(H25>=判定条件!$C$12,"利用可","不可") -> 利用可 | J25: =COUNTIFS(時間ごとの判定!$A$3:$A$1850,$A25,時間ごとの判定!$B$3:$B$1850,">="&判定条件!$C$10,時間ごとの判定!$B$3:$B$1850,"<="&判定条件!$C$11,時間ごとの判定!$AQ$3:$AQ$1850,"利用可") -> 9 | K25: =IF(J25>=判定条件!$C$12,"利用可","不可") -> 利用可 | L25: =COUNTIFS(時間ごとの判定!$A$3:$A$1850,$A25,時間ごとの判定!$B$3:$B$1850,">="&判定条件!$C$10,時間ごとの判定!$B$3:$B$1850,"<="&判定条件!$C$11,時間ごとの判定!$AT$3:$AT$1850,"利用可") -> 8 | M25: =IF(L25>=判定条件!$C$12,"利用可","不可") -> 利用可 | N25: =COUNTIFS(時間ごとの判定!$A$3:$A$1850,$A25,時間ごとの判定!$B$3:$B$1850,">="&判定条件!$C$10,時間ごとの判定!$B$3:$B$1850,"<="&判定条件!$C$11,時間ごとの判定!$AW$3:$AW$1850,"利用可") -> 9 | O25: =IF(N25>=判定条件!$C$12,"利用可","不可") -> 利用可 | P25: =IF(AND(E25="利用可",G25="利用可",I25="利用可"),"利用可","不可") -> 不可 | Q25: =IF(AND(K25="利用可",M25="利用可",O25="利用可"),"利用可","不可") -> 利用可 | R25: 8-2の排気・吸気温度が欠け（判定不能）
A26: 46255 | B26: 金 | C26: 平日 | D26: =COUNTIFS(時間ごとの判定!$A$3:$A$1850,$A26,時間ごとの判定!$B$3:$B$1850,">="&判定条件!$C$10,時間ごとの判定!$B$3:$B$1850,"<="&判定条件!$C$11,時間ごとの判定!$AH$3:$AH$1850,"利用可") -> 9 | E26: =IF(D26>=判定条件!$C$12,"利用可","不可") -> 利用可 | F26: =COUNTIFS(時間ごとの判定!$A$3:$A$1850,$A26,時間ごとの判定!$B$3:$B$1850,">="&判定条件!$C$10,時間ごとの判定!$B$3:$B$1850,"<="&判定条件!$C$11,時間ごとの判定!$AK$3:$AK$1850,"利用可") -> 0 | G26: =IF(F26>=判定条件!$C$12,"利用可","不可") -> 不可 | H26: =COUNTIFS(時間ごとの判定!$A$3:$A$1850,$A26,時間ごとの判定!$B$3:$B$1850,">="&判定条件!$C$10,時間ごとの判定!$B$3:$B$1850,"<="&判定条件!$C$11,時間ごとの判定!$AN$3:$AN$1850,"利用可") -> 9 | I26: =IF(H26>=判定条件!$C$12,"利用可","不可") -> 利用可 | J26: =COUNTIFS(時間ごとの判定!$A$3:$A$1850,$A26,時間ごとの判定!$B$3:$B$1850,">="&判定条件!$C$10,時間ごとの判定!$B$3:$B$1850,"<="&判定条件!$C$11,時間ごとの判定!$AQ$3:$AQ$1850,"利用可") -> 9 | K26: =IF(J26>=判定条件!$C$12,"利用可","不可") -> 利用可 | L26: =COUNTIFS(時間ごとの判定!$A$3:$A$1850,$A26,時間ごとの判定!$B$3:$B$1850,">="&判定条件!$C$10,時間ごとの判定!$B$3:$B$1850,"<="&判定条件!$C$11,時間ごとの判定!$AT$3:$AT$1850,"利用可") -> 9 | M26: =IF(L26>=判定条件!$C$12,"利用可","不可") -> 利用可 | N26: =COUNTIFS(時間ごとの判定!$A$3:$A$1850,$A26,時間ごとの判定!$B$3:$B$1850,">="&判定条件!$C$10,時間ごとの判定!$B$3:$B$1850,"<="&判定条件!$C$11,時間ごとの判定!$AW$3:$AW$1850,"利用可") -> 9 | O26: =IF(N26>=判定条件!$C$12,"利用可","不可") -> 利用可 | P26: =IF(AND(E26="利用可",G26="利用可",I26="利用可"),"利用可","不可") -> 不可 | Q26: =IF(AND(K26="利用可",M26="利用可",O26="利用可"),"利用可","不可") -> 利用可 | R26: 8-2の排気・吸気温度が欠け（判定不能）
A27: 46256 | B27: 土 | C27: 土日 | D27: =COUNTIFS(時間ごとの判定!$A$3:$A$1850,$A27,時間ごとの判定!$B$3:$B$1850,">="&判定条件!$C$10,時間ごとの判定!$B$3:$B$1850,"<="&判定条件!$C$11,時間ごとの判定!$AH$3:$AH$1850,"利用可") -> 7 | E27: =IF(D27>=判定条件!$C$12,"利用可","不可") -> 利用可 | F27: =COUNTIFS(時間ごとの判定!$A$3:$A$1850,$A27,時間ごとの判定!$B$3:$B$1850,">="&判定条件!$C$10,時間ごとの判定!$B$3:$B$1850,"<="&判定条件!$C$11,時間ごとの判定!$AK$3:$AK$1850,"利用可") -> 0 | G27: =IF(F27>=判定条件!$C$12,"利用可","不可") -> 不可 | H27: =COUNTIFS(時間ごとの判定!$A$3:$A$1850,$A27,時間ごとの判定!$B$3:$B$1850,">="&判定条件!$C$10,時間ごとの判定!$B$3:$B$1850,"<="&判定条件!$C$11,時間ごとの判定!$AN$3:$AN$1850,"利用可") -> 4 | I27: =IF(H27>=判定条件!$C$12,"利用可","不可") -> 不可 | J27: =COUNTIFS(時間ごとの判定!$A$3:$A$1850,$A27,時間ごとの判定!$B$3:$B$1850,">="&判定条件!$C$10,時間ごとの判定!$B$3:$B$1850,"<="&判定条件!$C$11,時間ごとの判定!$AQ$3:$AQ$1850,"利用可") -> 8 | K27: =IF(J27>=判定条件!$C$12,"利用可","不可") -> 利用可 | L27: =COUNTIFS(時間ごとの判定!$A$3:$A$1850,$A27,時間ごとの判定!$B$3:$B$1850,">="&判定条件!$C$10,時間ごとの判定!$B$3:$B$1850,"<="&判定条件!$C$11,時間ごとの判定!$AT$3:$AT$1850,"利用可") -> 6 | M27: =IF(L27>=判定条件!$C$12,"利用可","不可") -> 不可 | N27: =COUNTIFS(時間ごとの判定!$A$3:$A$1850,$A27,時間ごとの判定!$B$3:$B$1850,">="&判定条件!$C$10,時間ごとの判定!$B$3:$B$1850,"<="&判定条件!$C$11,時間ごとの判定!$AW$3:$AW$1850,"利用可") -> 9 | O27: =IF(N27>=判定条件!$C$12,"利用可","不可") -> 利用可 | P27: =IF(AND(E27="利用可",G27="利用可",I27="利用可"),"利用可","不可") -> 不可 | Q27: =IF(AND(K27="利用可",M27="利用可",O27="利用可"),"利用可","不可") -> 不可 | R27: 8-2の排気・吸気温度が欠け（判定不能）
A28: 46257 | B28: 日 | C28: 土日 | D28: =COUNTIFS(時間ごとの判定!$A$3:$A$1850,$A28,時間ごとの判定!$B$3:$B$1850,">="&判定条件!$C$10,時間ごとの判定!$B$3:$B$1850,"<="&判定条件!$C$11,時間ごとの判定!$AH$3:$AH$1850,"利用可") -> 7 | E28: =IF(D28>=判定条件!$C$12,"利用可","不可") -> 利用可 | F28: =COUNTIFS(時間ごとの判定!$A$3:$A$1850,$A28,時間ごとの判定!$B$3:$B$1850,">="&判定条件!$C$10,時間ごとの判定!$B$3:$B$1850,"<="&判定条件!$C$11,時間ごとの判定!$AK$3:$AK$1850,"利用可") -> 0 | G28: =IF(F28>=判定条件!$C$12,"利用可","不可") -> 不可 | H28: =COUNTIFS(時間ごとの判定!$A$3:$A$1850,$A28,時間ごとの判定!$B$3:$B$1850,">="&判定条件!$C$10,時間ごとの判定!$B$3:$B$1850,"<="&判定条件!$C$11,時間ごとの判定!$AN$3:$AN$1850,"利用可") -> 3 | I28: =IF(H28>=判定条件!$C$12,"利用可","不可") -> 不可 | J28: =COUNTIFS(時間ごとの判定!$A$3:$A$1850,$A28,時間ごとの判定!$B$3:$B$1850,">="&判定条件!$C$10,時間ごとの判定!$B$3:$B$1850,"<="&判定条件!$C$11,時間ごとの判定!$AQ$3:$AQ$1850,"利用可") -> 7 | K28: =IF(J28>=判定条件!$C$12,"利用可","不可") -> 利用可 | L28: =COUNTIFS(時間ごとの判定!$A$3:$A$1850,$A28,時間ごとの判定!$B$3:$B$1850,">="&判定条件!$C$10,時間ごとの判定!$B$3:$B$1850,"<="&判定条件!$C$11,時間ごとの判定!$AT$3:$AT$1850,"利用可") -> 5 | M28: =IF(L28>=判定条件!$C$12,"利用可","不可") -> 不可 | N28: =COUNTIFS(時間ごとの判定!$A$3:$A$1850,$A28,時間ごとの判定!$B$3:$B$1850,">="&判定条件!$C$10,時間ごとの判定!$B$3:$B$1850,"<="&判定条件!$C$11,時間ごとの判定!$AW$3:$AW$1850,"利用可") -> 9 | O28: =IF(N28>=判定条件!$C$12,"利用可","不可") -> 利用可 | P28: =IF(AND(E28="利用可",G28="利用可",I28="利用可"),"利用可","不可") -> 不可 | Q28: =IF(AND(K28="利用可",M28="利用可",O28="利用可"),"利用可","不可") -> 不可 | R28: 8-2の排気・吸気温度が欠け（判定不能）
A29: 46258 | B29: 月 | C29: 平日 | D29: =COUNTIFS(時間ごとの判定!$A$3:$A$1850,$A29,時間ごとの判定!$B$3:$B$1850,">="&判定条件!$C$10,時間ごとの判定!$B$3:$B$1850,"<="&判定条件!$C$11,時間ごとの判定!$AH$3:$AH$1850,"利用可") -> 9 | E29: =IF(D29>=判定条件!$C$12,"利用可","不可") -> 利用可 | F29: =COUNTIFS(時間ごとの判定!$A$3:$A$1850,$A29,時間ごとの判定!$B$3:$B$1850,">="&判定条件!$C$10,時間ごとの判定!$B$3:$B$1850,"<="&判定条件!$C$11,時間ごとの判定!$AK$3:$AK$1850,"利用可") -> 0 | G29: =IF(F29>=判定条件!$C$12,"利用可","不可") -> 不可 | H29: =COUNTIFS(時間ごとの判定!$A$3:$A$1850,$A29,時間ごとの判定!$B$3:$B$1850,">="&判定条件!$C$10,時間ごとの判定!$B$3:$B$1850,"<="&判定条件!$C$11,時間ごとの判定!$AN$3:$AN$1850,"利用可") -> 9 | I29: =IF(H29>=判定条件!$C$12,"利用可","不可") -> 利用可 | J29: =COUNTIFS(時間ごとの判定!$A$3:$A$1850,$A29,時間ごとの判定!$B$3:$B$1850,">="&判定条件!$C$10,時間ごとの判定!$B$3:$B$1850,"<="&判定条件!$C$11,時間ごとの判定!$AQ$3:$AQ$1850,"利用可") -> 9 | K29: =IF(J29>=判定条件!$C$12,"利用可","不可") -> 利用可 | L29: =COUNTIFS(時間ごとの判定!$A$3:$A$1850,$A29,時間ごとの判定!$B$3:$B$1850,">="&判定条件!$C$10,時間ごとの判定!$B$3:$B$1850,"<="&判定条件!$C$11,時間ごとの判定!$AT$3:$AT$1850,"利用可") -> 9 | M29: =IF(L29>=判定条件!$C$12,"利用可","不可") -> 利用可 | N29: =COUNTIFS(時間ごとの判定!$A$3:$A$1850,$A29,時間ごとの判定!$B$3:$B$1850,">="&判定条件!$C$10,時間ごとの判定!$B$3:$B$1850,"<="&判定条件!$C$11,時間ごとの判定!$AW$3:$AW$1850,"利用可") -> 9 | O29: =IF(N29>=判定条件!$C$12,"利用可","不可") -> 利用可 | P29: =IF(AND(E29="利用可",G29="利用可",I29="利用可"),"利用可","不可") -> 不可 | Q29: =IF(AND(K29="利用可",M29="利用可",O29="利用可"),"利用可","不可") -> 利用可 | R29: 8-2の排気・吸気温度が欠け（判定不能）
A30: 46259 | B30: 火 | C30: 平日 | D30: =COUNTIFS(時間ごとの判定!$A$3:$A$1850,$A30,時間ごとの判定!$B$3:$B$1850,">="&判定条件!$C$10,時間ごとの判定!$B$3:$B$1850,"<="&判定条件!$C$11,時間ごとの判定!$AH$3:$AH$1850,"利用可") -> 9 | E30: =IF(D30>=判定条件!$C$12,"利用可","不可") -> 利用可 | F30: =COUNTIFS(時間ごとの判定!$A$3:$A$1850,$A30,時間ごとの判定!$B$3:$B$1850,">="&判定条件!$C$10,時間ごとの判定!$B$3:$B$1850,"<="&判定条件!$C$11,時間ごとの判定!$AK$3:$AK$1850,"利用可") -> 0 | G30: =IF(F30>=判定条件!$C$12,"利用可","不可") -> 不可 | H30: =COUNTIFS(時間ごとの判定!$A$3:$A$1850,$A30,時間ごとの判定!$B$3:$B$1850,">="&判定条件!$C$10,時間ごとの判定!$B$3:$B$1850,"<="&判定条件!$C$11,時間ごとの判定!$AN$3:$AN$1850,"利用可") -> 9 | I30: =IF(H30>=判定条件!$C$12,"利用可","不可") -> 利用可 | J30: =COUNTIFS(時間ごとの判定!$A$3:$A$1850,$A30,時間ごとの判定!$B$3:$B$1850,">="&判定条件!$C$10,時間ごとの判定!$B$3:$B$1850,"<="&判定条件!$C$11,時間ごとの判定!$AQ$3:$AQ$1850,"利用可") -> 9 | K30: =IF(J30>=判定条件!$C$12,"利用可","不可") -> 利用可 | L30: =COUNTIFS(時間ごとの判定!$A$3:$A$1850,$A30,時間ごとの判定!$B$3:$B$1850,">="&判定条件!$C$10,時間ごとの判定!$B$3:$B$1850,"<="&判定条件!$C$11,時間ごとの判定!$AT$3:$AT$1850,"利用可") -> 9 | M30: =IF(L30>=判定条件!$C$12,"利用可","不可") -> 利用可 | N30: =COUNTIFS(時間ごとの判定!$A$3:$A$1850,$A30,時間ごとの判定!$B$3:$B$1850,">="&判定条件!$C$10,時間ごとの判定!$B$3:$B$1850,"<="&判定条件!$C$11,時間ごとの判定!$AW$3:$AW$1850,"利用可") -> 9 | O30: =IF(N30>=判定条件!$C$12,"利用可","不可") -> 利用可 | P30: =IF(AND(E30="利用可",G30="利用可",I30="利用可"),"利用可","不可") -> 不可 | Q30: =IF(AND(K30="利用可",M30="利用可",O30="利用可"),"利用可","不可") -> 利用可 | R30: 8-2の排気・吸気温度が欠け（判定不能）
... A33: 46262 | B33: 金 | C33: 平日 | D33: =COUNTIFS(時間ごとの判定!$A$3:$A$1850,$A33,時間ごとの判定!$B$3:$B$1850,">="&判定条件!$C$10,時間ごとの判定!$B$3:$B$1850,"<="&判定条件!$C$11,時間ごとの判定!$AH$3:$AH$1850,"利用可") -> 6 | E33: =IF(D33>=判定条件!$C$12,"利用可","不可") -> 不可 | F33: =COUNTIFS(時間ごとの判定!$A$3:$A$1850,$A33,時間ごとの判定!$B$3:$B$1850,">="&判定条件!$C$10,時間ごとの判定!$B$3:$B$1850,"<="&判定条件!$C$11,時間ごとの判定!$AK$3:$AK$1850,"利用可") -> 6 | G33: =IF(F33>=判定条件!$C$12,"利用可","不可") -> 不可 | H33: =COUNTIFS(時間ごとの判定!$A$3:$A$1850,$A33,時間ごとの判定!$B$3:$B$1850,">="&判定条件!$C$10,時間ごとの判定!$B$3:$B$1850,"<="&判定条件!$C$11,時間ごとの判定!$AN$3:$AN$1850,"利用可") -> 7 | I33: =IF(H33>=判定条件!$C$12,"利用可","不可") -> 利用可 | J33: =COUNTIFS(時間ごとの判定!$A$3:$A$1850,$A33,時間ごとの判定!$B$3:$B$1850,">="&判定条件!$C$10,時間ごとの判定!$B$3:$B$1850,"<="&判定条件!$C$11,時間ごとの判定!$AQ$3:$AQ$1850,"利用可") -> 9 | K33: =IF(J33>=判定条件!$C$12,"利用可","不可") -> 利用可 | L33: =COUNTIFS(時間ごとの判定!$A$3:$A$1850,$A33,時間ごとの判定!$B$3:$B$1850,">="&判定条件!$C$10,時間ごとの判定!$B$3:$B$1850,"<="&判定条件!$C$11,時間ごとの判定!$AT$3:$AT$1850,"利用可") -> 9 | M33: =IF(L33>=判定条件!$C$12,"利用可","不可") -> 利用可 | N33: =COUNTIFS(時間ごとの判定!$A$3:$A$1850,$A33,時間ごとの判定!$B$3:$B$1850,">="&判定条件!$C$10,時間ごとの判定!$B$3:$B$1850,"<="&判定条件!$C$11,時間ごとの判定!$AW$3:$AW$1850,"利用可") -> 9 | O33: =IF(N33>=判定条件!$C$12,"利用可","不可") -> 利用可 | P33: =IF(AND(E33="利用可",G33="利用可",I33="利用可"),"利用可","不可") -> 不可 | Q33: =IF(AND(K33="利用可",M33="利用可",O33="利用可"),"利用可","不可") -> 利用可 | R33: 8-2の排気・吸気温度が欠け（判定不能）
A34: 46263 | B34: 土 | C34: 土日 | D34: =COUNTIFS(時間ごとの判定!$A$3:$A$1850,$A34,時間ごとの判定!$B$3:$B$1850,">="&判定条件!$C$10,時間ごとの判定!$B$3:$B$1850,"<="&判定条件!$C$11,時間ごとの判定!$AH$3:$AH$1850,"利用可") -> 0 | E34: =IF(D34>=判定条件!$C$12,"利用可","不可") -> 不可 | F34: =COUNTIFS(時間ごとの判定!$A$3:$A$1850,$A34,時間ごとの判定!$B$3:$B$1850,">="&判定条件!$C$10,時間ごとの判定!$B$3:$B$1850,"<="&判定条件!$C$11,時間ごとの判定!$AK$3:$AK$1850,"利用可") -> 4 | G34: =IF(F34>=判定条件!$C$12,"利用可","不可") -> 不可 | H34: =COUNTIFS(時間ごとの判定!$A$3:$A$1850,$A34,時間ごとの判定!$B$3:$B$1850,">="&判定条件!$C$10,時間ごとの判定!$B$3:$B$1850,"<="&判定条件!$C$11,時間ごとの判定!$AN$3:$AN$1850,"利用可") -> 6 | I34: =IF(H34>=判定条件!$C$12,"利用可","不可") -> 不可 | J34: =COUNTIFS(時間ごとの判定!$A$3:$A$1850,$A34,時間ごとの判定!$B$3:$B$1850,">="&判定条件!$C$10,時間ごとの判定!$B$3:$B$1850,"<="&判定条件!$C$11,時間ごとの判定!$AQ$3:$AQ$1850,"利用可") -> 7 | K34: =IF(J34>=判定条件!$C$12,"利用可","不可") -> 利用可 | L34: =COUNTIFS(時間ごとの判定!$A$3:$A$1850,$A34,時間ごとの判定!$B$3:$B$1850,">="&判定条件!$C$10,時間ごとの判定!$B$3:$B$1850,"<="&判定条件!$C$11,時間ごとの判定!$AT$3:$AT$1850,"利用可") -> 3 | M34: =IF(L34>=判定条件!$C$12,"利用可","不可") -> 不可 | N34: =COUNTIFS(時間ごとの判定!$A$3:$A$1850,$A34,時間ごとの判定!$B$3:$B$1850,">="&判定条件!$C$10,時間ごとの判定!$B$3:$B$1850,"<="&判定条件!$C$11,時間ごとの判定!$AW$3:$AW$1850,"利用可") -> 9 | O34: =IF(N34>=判定条件!$C$12,"利用可","不可") -> 利用可 | P34: =IF(AND(E34="利用可",G34="利用可",I34="利用可"),"利用可","不可") -> 不可 | Q34: =IF(AND(K34="利用可",M34="利用可",O34="利用可"),"利用可","不可") -> 不可
A35: 46264 | B35: 日 | C35: 土日 | D35: =COUNTIFS(時間ごとの判定!$A$3:$A$1850,$A35,時間ごとの判定!$B$3:$B$1850,">="&判定条件!$C$10,時間ごとの判定!$B$3:$B$1850,"<="&判定条件!$C$11,時間ごとの判定!$AH$3:$AH$1850,"利用可") -> 7 | E35: =IF(D35>=判定条件!$C$12,"利用可","不可") -> 利用可 | F35: =COUNTIFS(時間ごとの判定!$A$3:$A$1850,$A35,時間ごとの判定!$B$3:$B$1850,">="&判定条件!$C$10,時間ごとの判定!$B$3:$B$1850,"<="&判定条件!$C$11,時間ごとの判定!$AK$3:$AK$1850,"利用可") -> 0 | G35: =IF(F35>=判定条件!$C$12,"利用可","不可") -> 不可 | H35: =COUNTIFS(時間ごとの判定!$A$3:$A$1850,$A35,時間ごとの判定!$B$3:$B$1850,">="&判定条件!$C$10,時間ごとの判定!$B$3:$B$1850,"<="&判定条件!$C$11,時間ごとの判定!$AN$3:$AN$1850,"利用可") -> 5 | I35: =IF(H35>=判定条件!$C$12,"利用可","不可") -> 不可 | J35: =COUNTIFS(時間ごとの判定!$A$3:$A$1850,$A35,時間ごとの判定!$B$3:$B$1850,">="&判定条件!$C$10,時間ごとの判定!$B$3:$B$1850,"<="&判定条件!$C$11,時間ごとの判定!$AQ$3:$AQ$1850,"利用可") -> 7 | K35: =IF(J35>=判定条件!$C$12,"利用可","不可") -> 利用可 | L35: =COUNTIFS(時間ごとの判定!$A$3:$A$1850,$A35,時間ごとの判定!$B$3:$B$1850,">="&判定条件!$C$10,時間ごとの判定!$B$3:$B$1850,"<="&判定条件!$C$11,時間ごとの判定!$AT$3:$AT$1850,"利用可") -> 0 | M35: =IF(L35>=判定条件!$C$12,"利用可","不可") -> 不可 | N35: =COUNTIFS(時間ごとの判定!$A$3:$A$1850,$A35,時間ごとの判定!$B$3:$B$1850,">="&判定条件!$C$10,時間ごとの判定!$B$3:$B$1850,"<="&判定条件!$C$11,時間ごとの判定!$AW$3:$AW$1850,"利用可") -> 8 | O35: =IF(N35>=判定条件!$C$12,"利用可","不可") -> 利用可 | P35: =IF(AND(E35="利用可",G35="利用可",I35="利用可"),"利用可","不可") -> 不可 | Q35: =IF(AND(K35="利用可",M35="利用可",O35="利用可"),"利用可","不可") -> 不可 | R35: 3-2の排気・吸気温度が欠け（判定不能）
A36: 46265 | B36: 月 | C36: 平日 | D36: =COUNTIFS(時間ごとの判定!$A$3:$A$1850,$A36,時間ごとの判定!$B$3:$B$1850,">="&判定条件!$C$10,時間ごとの判定!$B$3:$B$1850,"<="&判定条件!$C$11,時間ごとの判定!$AH$3:$AH$1850,"利用可") -> 8 | E36: =IF(D36>=判定条件!$C$12,"利用可","不可") -> 利用可 | F36: =COUNTIFS(時間ごとの判定!$A$3:$A$1850,$A36,時間ごとの判定!$B$3:$B$1850,">="&判定条件!$C$10,時間ごとの判定!$B$3:$B$1850,"<="&判定条件!$C$11,時間ごとの判定!$AK$3:$AK$1850,"利用可") -> 0 | G36: =IF(F36>=判定条件!$C$12,"利用可","不可") -> 不可 | H36: =COUNTIFS(時間ごとの判定!$A$3:$A$1850,$A36,時間ごとの判定!$B$3:$B$1850,">="&判定条件!$C$10,時間ごとの判定!$B$3:$B$1850,"<="&判定条件!$C$11,時間ごとの判定!$AN$3:$AN$1850,"利用可") -> 8 | I36: =IF(H36>=判定条件!$C$12,"利用可","不可") -> 利用可 | J36: =COUNTIFS(時間ごとの判定!$A$3:$A$1850,$A36,時間ごとの判定!$B$3:$B$1850,">="&判定条件!$C$10,時間ごとの判定!$B$3:$B$1850,"<="&判定条件!$C$11,時間ごとの判定!$AQ$3:$AQ$1850,"利用可") -> 8 | K36: =IF(J36>=判定条件!$C$12,"利用可","不可") -> 利用可 | L36: =COUNTIFS(時間ごとの判定!$A$3:$A$1850,$A36,時間ごとの判定!$B$3:$B$1850,">="&判定条件!$C$10,時間ごとの判定!$B$3:$B$1850,"<="&判定条件!$C$11,時間ごとの判定!$AT$3:$AT$1850,"利用可") -> 0 | M36: =IF(L36>=判定条件!$C$12,"利用可","不可") -> 不可 | N36: =COUNTIFS(時間ごとの判定!$A$3:$A$1850,$A36,時間ごとの判定!$B$3:$B$1850,">="&判定条件!$C$10,時間ごとの判定!$B$3:$B$1850,"<="&判定条件!$C$11,時間ごとの判定!$AW$3:$AW$1850,"利用可") -> 9 | O36: =IF(N36>=判定条件!$C$12,"利用可","不可") -> 利用可 | P36: =IF(AND(E36="利用可",G36="利用可",I36="利用可"),"利用可","不可") -> 不可 | Q36: =IF(AND(K36="利用可",M36="利用可",O36="利用可"),"利用可","不可") -> 不可 | R36: 3-2の排気・吸気温度が欠け（判定不能）
A37: 46266 | B37: 火 | C37: 平日 | D37: =COUNTIFS(時間ごとの判定!$A$3:$A$1850,$A37,時間ごとの判定!$B$3:$B$1850,">="&判定条件!$C$10,時間ごとの判定!$B$3:$B$1850,"<="&判定条件!$C$11,時間ごとの判定!$AH$3:$AH$1850,"利用可") -> 8 | E37: =IF(D37>=判定条件!$C$12,"利用可","不可") -> 利用可 | F37: =COUNTIFS(時間ごとの判定!$A$3:$A$1850,$A37,時間ごとの判定!$B$3:$B$1850,">="&判定条件!$C$10,時間ごとの判定!$B$3:$B$1850,"<="&判定条件!$C$11,時間ごとの判定!$AK$3:$AK$1850,"利用可") -> 0 | G37: =IF(F37>=判定条件!$C$12,"利用可","不可") -> 不可 | H37: =COUNTIFS(時間ごとの判定!$A$3:$A$1850,$A37,時間ごとの判定!$B$3:$B$1850,">="&判定条件!$C$10,時間ごとの判定!$B$3:$B$1850,"<="&判定条件!$C$11,時間ごとの判定!$AN$3:$AN$1850,"利用可") -> 9 | I37: =IF(H37>=判定条件!$C$12,"利用可","不可") -> 利用可 | J37: =COUNTIFS(時間ごとの判定!$A$3:$A$1850,$A37,時間ごとの判定!$B$3:$B$1850,">="&判定条件!$C$10,時間ごとの判定!$B$3:$B$1850,"<="&判定条件!$C$11,時間ごとの判定!$AQ$3:$AQ$1850,"利用可") -> 8 | K37: =IF(J37>=判定条件!$C$12,"利用可","不可") -> 利用可 | L37: =COUNTIFS(時間ごとの判定!$A$3:$A$1850,$A37,時間ごとの判定!$B$3:$B$1850,">="&判定条件!$C$10,時間ごとの判定!$B$3:$B$1850,"<="&判定条件!$C$11,時間ごとの判定!$AT$3:$AT$1850,"利用可") -> 0 | M37: =IF(L37>=判定条件!$C$12,"利用可","不可") -> 不可 | N37: =COUNTIFS(時間ごとの判定!$A$3:$A$1850,$A37,時間ごとの判定!$B$3:$B$1850,">="&判定条件!$C$10,時間ごとの判定!$B$3:$B$1850,"<="&判定条件!$C$11,時間ごとの判定!$AW$3:$AW$1850,"利用可") -> 9 | O37: =IF(N37>=判定条件!$C$12,"利用可","不可") -> 利用可 | P37: =IF(AND(E37="利用可",G37="利用可",I37="利用可"),"利用可","不可") -> 不可 | Q37: =IF(AND(K37="利用可",M37="利用可",O37="利用可"),"利用可","不可") -> 不可 | R37: 3-2の排気・吸気温度が欠け（判定不能）
A38: 46267 | B38: 水 | C38: 平日 | D38: =COUNTIFS(時間ごとの判定!$A$3:$A$1850,$A38,時間ごとの判定!$B$3:$B$1850,">="&判定条件!$C$10,時間ごとの判定!$B$3:$B$1850,"<="&判定条件!$C$11,時間ごとの判定!$AH$3:$AH$1850,"利用可") -> 9 | E38: =IF(D38>=判定条件!$C$12,"利用可","不可") -> 利用可 | F38: =COUNTIFS(時間ごとの判定!$A$3:$A$1850,$A38,時間ごとの判定!$B$3:$B$1850,">="&判定条件!$C$10,時間ごとの判定!$B$3:$B$1850,"<="&判定条件!$C$11,時間ごとの判定!$AK$3:$AK$1850,"利用可") -> 0 | G38: =IF(F38>=判定条件!$C$12,"利用可","不可") -> 不可 | H38: =COUNTIFS(時間ごとの判定!$A$3:$A$1850,$A38,時間ごとの判定!$B$3:$B$1850,">="&判定条件!$C$10,時間ごとの判定!$B$3:$B$1850,"<="&判定条件!$C$11,時間ごとの判定!$AN$3:$AN$1850,"利用可") -> 9 | I38: =IF(H38>=判定条件!$C$12,"利用可","不可") -> 利用可 | J38: =COUNTIFS(時間ごとの判定!$A$3:$A$1850,$A38,時間ごとの判定!$B$3:$B$1850,">="&判定条件!$C$10,時間ごとの判定!$B$3:$B$1850,"<="&判定条件!$C$11,時間ごとの判定!$AQ$3:$AQ$1850,"利用可") -> 9 | K38: =IF(J38>=判定条件!$C$12,"利用可","不可") -> 利用可 | L38: =COUNTIFS(時間ごとの判定!$A$3:$A$1850,$A38,時間ごとの判定!$B$3:$B$1850,">="&判定条件!$C$10,時間ごとの判定!$B$3:$B$1850,"<="&判定条件!$C$11,時間ごとの判定!$AT$3:$AT$1850,"利用可") -> 0 | M38: =IF(L38>=判定条件!$C$12,"利用可","不可") -> 不可 | N38: =COUNTIFS(時間ごとの判定!$A$3:$A$1850,$A38,時間ごとの判定!$B$3:$B$1850,">="&判定条件!$C$10,時間ごとの判定!$B$3:$B$1850,"<="&判定条件!$C$11,時間ごとの判定!$AW$3:$AW$1850,"利用可") -> 9 | O38: =IF(N38>=判定条件!$C$12,"利用可","不可") -> 利用可 | P38: =IF(AND(E38="利用可",G38="利用可",I38="利用可"),"利用可","不可") -> 不可 | Q38: =IF(AND(K38="利用可",M38="利用可",O38="利用可"),"利用可","不可") -> 不可 | R38: 3-2の排気・吸気温度が欠け（判定不能）
A39: 46268 | B39: 木 | C39: 平日 | D39: =COUNTIFS(時間ごとの判定!$A$3:$A$1850,$A39,時間ごとの判定!$B$3:$B$1850,">="&判定条件!$C$10,時間ごとの判定!$B$3:$B$1850,"<="&判定条件!$C$11,時間ごとの判定!$AH$3:$AH$1850,"利用可") -> 9 | E39: =IF(D39>=判定条件!$C$12,"利用可","不可") -> 利用可 | F39: =COUNTIFS(時間ごとの判定!$A$3:$A$1850,$A39,時間ごとの判定!$B$3:$B$1850,">="&判定条件!$C$10,時間ごとの判定!$B$3:$B$1850,"<="&判定条件!$C$11,時間ごとの判定!$AK$3:$AK$1850,"利用可") -> 0 | G39: =IF(F39>=判定条件!$C$12,"利用可","不可") -> 不可 | H39: =COUNTIFS(時間ごとの判定!$A$3:$A$1850,$A39,時間ごとの判定!$B$3:$B$1850,">="&判定条件!$C$10,時間ごとの判定!$B$3:$B$1850,"<="&判定条件!$C$11,時間ごとの判定!$AN$3:$AN$1850,"利用可") -> 9 | I39: =IF(H39>=判定条件!$C$12,"利用可","不可") -> 利用可 | J39: =COUNTIFS(時間ごとの判定!$A$3:$A$1850,$A39,時間ごとの判定!$B$3:$B$1850,">="&判定条件!$C$10,時間ごとの判定!$B$3:$B$1850,"<="&判定条件!$C$11,時間ごとの判定!$AQ$3:$AQ$1850,"利用可") -> 8 | K39: =IF(J39>=判定条件!$C$12,"利用可","不可") -> 利用可 | L39: =COUNTIFS(時間ごとの判定!$A$3:$A$1850,$A39,時間ごとの判定!$B$3:$B$1850,">="&判定条件!$C$10,時間ごとの判定!$B$3:$B$1850,"<="&判定条件!$C$11,時間ごとの判定!$AT$3:$AT$1850,"利用可") -> 0 | M39: =IF(L39>=判定条件!$C$12,"利用可","不可") -> 不可 | N39: =COUNTIFS(時間ごとの判定!$A$3:$A$1850,$A39,時間ごとの判定!$B$3:$B$1850,">="&判定条件!$C$10,時間ごとの判定!$B$3:$B$1850,"<="&判定条件!$C$11,時間ごとの判定!$AW$3:$AW$1850,"利用可") -> 9 | O39: =IF(N39>=判定条件!$C$12,"利用可","不可") -> 利用可 | P39: =IF(AND(E39="利用可",G39="利用可",I39="利用可"),"利用可","不可") -> 不可 | Q39: =IF(AND(K39="利用可",M39="利用可",O39="利用可"),"利用可","不可") -> 不可 | R39: 3-2の排気・吸気温度が欠け（判定不能）
A40: 46269 | B40: 金 | C40: 平日 | D40: =COUNTIFS(時間ごとの判定!$A$3:$A$1850,$A40,時間ごとの判定!$B$3:$B$1850,">="&判定条件!$C$10,時間ごとの判定!$B$3:$B$1850,"<="&判定条件!$C$11,時間ごとの判定!$AH$3:$AH$1850,"利用可") -> 6 | E40: =IF(D40>=判定条件!$C$12,"利用可","不可") -> 不可 | F40: =COUNTIFS(時間ごとの判定!$A$3:$A$1850,$A40,時間ごとの判定!$B$3:$B$1850,">="&判定条件!$C$10,時間ごとの判定!$B$3:$B$1850,"<="&判定条件!$C$11,時間ごとの判定!$AK$3:$AK$1850,"利用可") -> 0 | G40: =IF(F40>=判定条件!$C$12,"利用可","不可") -> 不可 | H40: =COUNTIFS(時間ごとの判定!$A$3:$A$1850,$A40,時間ごとの判定!$B$3:$B$1850,">="&判定条件!$C$10,時間ごとの判定!$B$3:$B$1850,"<="&判定条件!$C$11,時間ごとの判定!$AN$3:$AN$1850,"利用可") -> 9 | I40: =IF(H40>=判定条件!$C$12,"利用可","不可") -> 利用可 | J40: =COUNTIFS(時間ごとの判定!$A$3:$A$1850,$A40,時間ごとの判定!$B$3:$B$1850,">="&判定条件!$C$10,時間ごとの判定!$B$3:$B$1850,"<="&判定条件!$C$11,時間ごとの判定!$AQ$3:$AQ$1850,"利用可") -> 6 | K40: =IF(J40>=判定条件!$C$12,"利用可","不可") -> 不可 | L40: =COUNTIFS(時間ごとの判定!$A$3:$A$1850,$A40,時間ごとの判定!$B$3:$B$1850,">="&判定条件!$C$10,時間ごとの判定!$B$3:$B$1850,"<="&判定条件!$C$11,時間ごとの判定!$AT$3:$AT$1850,"利用可") -> 0 | M40: =IF(L40>=判定条件!$C$12,"利用可","不可") -> 不可 | N40: =COUNTIFS(時間ごとの判定!$A$3:$A$1850,$A40,時間ごとの判定!$B$3:$B$1850,">="&判定条件!$C$10,時間ごとの判定!$B$3:$B$1850,"<="&判定条件!$C$11,時間ごとの判定!$AW$3:$AW$1850,"利用可") -> 9 | O40: =IF(N40>=判定条件!$C$12,"利用可","不可") -> 利用可 | P40: =IF(AND(E40="利用可",G40="利用可",I40="利用可"),"利用可","不可") -> 不可 | Q40: =IF(AND(K40="利用可",M40="利用可",O40="利用可"),"利用可","不可") -> 不可 | R40: 3-2の排気・吸気温度が欠け（判定不能）
A41: 46270 | B41: 土 | C41: 土日 | D41: =COUNTIFS(時間ごとの判定!$A$3:$A$1850,$A41,時間ごとの判定!$B$3:$B$1850,">="&判定条件!$C$10,時間ごとの判定!$B$3:$B$1850,"<="&判定条件!$C$11,時間ごとの判定!$AH$3:$AH$1850,"利用可") -> 6 | E41: =IF(D41>=判定条件!$C$12,"利用可","不可") -> 不可 | F41: =COUNTIFS(時間ごとの判定!$A$3:$A$1850,$A41,時間ごとの判定!$B$3:$B$1850,">="&判定条件!$C$10,時間ごとの判定!$B$3:$B$1850,"<="&判定条件!$C$11,時間ごとの判定!$AK$3:$AK$1850,"利用可") -> 5 | G41: =IF(F41>=判定条件!$C$12,"利用可","不可") -> 不可 | H41: =COUNTIFS(時間ごとの判定!$A$3:$A$1850,$A41,時間ごとの判定!$B$3:$B$1850,">="&判定条件!$C$10,時間ごとの判定!$B$3:$B$1850,"<="&判定条件!$C$11,時間ごとの判定!$AN$3:$AN$1850,"利用可") -> 5 | I41: =IF(H41>=判定条件!$C$12,"利用可","不可") -> 不可 | J41: =COUNTIFS(時間ごとの判定!$A$3:$A$1850,$A41,時間ごとの判定!$B$3:$B$1850,">="&判定条件!$C$10,時間ごとの判定!$B$3:$B$1850,"<="&判定条件!$C$11,時間ごとの判定!$AQ$3:$AQ$1850,"利用可") -> 5 | K41: =IF(J41>=判定条件!$C$12,"利用可","不可") -> 不可 | L41: =COUNTIFS(時間ごとの判定!$A$3:$A$1850,$A41,時間ごとの判定!$B$3:$B$1850,">="&判定条件!$C$10,時間ごとの判定!$B$3:$B$1850,"<="&判定条件!$C$11,時間ごとの判定!$AT$3:$AT$1850,"利用可") -> 3 | M41: =IF(L41>=判定条件!$C$12,"利用可","不可") -> 不可 | N41: =COUNTIFS(時間ごとの判定!$A$3:$A$1850,$A41,時間ごとの判定!$B$3:$B$1850,">="&判定条件!$C$10,時間ごとの判定!$B$3:$B$1850,"<="&判定条件!$C$11,時間ごとの判定!$AW$3:$AW$1850,"利用可") -> 9 | O41: =IF(N41>=判定条件!$C$12,"利用可","不可") -> 利用可 | P41: =IF(AND(E41="利用可",G41="利用可",I41="利用可"),"利用可","不可") -> 不可 | Q41: =IF(AND(K41="利用可",M41="利用可",O41="利用可"),"利用可","不可") -> 不可
A42: 46271 | B42: 日 | C42: 土日 | D42: =COUNTIFS(時間ごとの判定!$A$3:$A$1850,$A42,時間ごとの判定!$B$3:$B$1850,">="&判定条件!$C$10,時間ごとの判定!$B$3:$B$1850,"<="&判定条件!$C$11,時間ごとの判定!$AH$3:$AH$1850,"利用可") -> 0 | E42: =IF(D42>=判定条件!$C$12,"利用可","不可") -> 不可 | F42: =COUNTIFS(時間ごとの判定!$A$3:$A$1850,$A42,時間ごとの判定!$B$3:$B$1850,">="&判定条件!$C$10,時間ごとの判定!$B$3:$B$1850,"<="&判定条件!$C$11,時間ごとの判定!$AK$3:$AK$1850,"利用可") -> 0 | G42: =IF(F42>=判定条件!$C$12,"利用可","不可") -> 不可 | H42: =COUNTIFS(時間ごとの判定!$A$3:$A$1850,$A42,時間ごとの判定!$B$3:$B$1850,">="&判定条件!$C$10,時間ごとの判定!$B$3:$B$1850,"<="&判定条件!$C$11,時間ごとの判定!$AN$3:$AN$1850,"利用可") -> 0 | I42: =IF(H42>=判定条件!$C$12,"利用可","不可") -> 不可 | J42: =COUNTIFS(時間ごとの判定!$A$3:$A$1850,$A42,時間ごとの判定!$B$3:$B$1850,">="&判定条件!$C$10,時間ごとの判定!$B$3:$B$1850,"<="&判定条件!$C$11,時間ごとの判定!$AQ$3:$AQ$1850,"利用可") -> 0 | K42: =IF(J42>=判定条件!$C$12,"利用可","不可") -> 不可 | L42: =COUNTIFS(時間ごとの判定!$A$3:$A$1850,$A42,時間ごとの判定!$B$3:$B$1850,">="&判定条件!$C$10,時間ごとの判定!$B$3:$B$1850,"<="&判定条件!$C$11,時間ごとの判定!$AT$3:$AT$1850,"利用可") -> 0 | M42: =IF(L42>=判定条件!$C$12,"利用可","不可") -> 不可 | N42: =COUNTIFS(時間ごとの判定!$A$3:$A$1850,$A42,時間ごとの判定!$B$3:$B$1850,">="&判定条件!$C$10,時間ごとの判定!$B$3:$B$1850,"<="&判定条件!$C$11,時間ごとの判定!$AW$3:$AW$1850,"利用可") -> 9 | O42: =IF(N42>=判定条件!$C$12,"利用可","不可") -> 利用可 | P42: =IF(AND(E42="利用可",G42="利用可",I42="利用可"),"利用可","不可") -> 不可 | Q42: =IF(AND(K42="利用可",M42="利用可",O42="利用可"),"利用可","不可") -> 不可 | R42: 3-2の排気・吸気温度が欠け（判定不能）
A43: 46272 | B43: 月 | C43: 平日 | D43: =COUNTIFS(時間ごとの判定!$A$3:$A$1850,$A43,時間ごとの判定!$B$3:$B$1850,">="&判定条件!$C$10,時間ごとの判定!$B$3:$B$1850,"<="&判定条件!$C$11,時間ごとの判定!$AH$3:$AH$1850,"利用可") -> 4 | E43: =IF(D43>=判定条件!$C$12,"利用可","不可") -> 不可 | F43: =COUNTIFS(時間ごとの判定!$A$3:$A$1850,$A43,時間ごとの判定!$B$3:$B$1850,">="&判定条件!$C$10,時間ごとの判定!$B$3:$B$1850,"<="&判定条件!$C$11,時間ごとの判定!$AK$3:$AK$1850,"利用可") -> 0 | G43: =IF(F43>=判定条件!$C$12,"利用可","不可") -> 不可 | H43: =COUNTIFS(時間ごとの判定!$A$3:$A$1850,$A43,時間ごとの判定!$B$3:$B$1850,">="&判定条件!$C$10,時間ごとの判定!$B$3:$B$1850,"<="&判定条件!$C$11,時間ごとの判定!$AN$3:$AN$1850,"利用可") -> 5 | I43: =IF(H43>=判定条件!$C$12,"利用可","不可") -> 不可 | J43: =COUNTIFS(時間ごとの判定!$A$3:$A$1850,$A43,時間ごとの判定!$B$3:$B$1850,">="&判定条件!$C$10,時間ごとの判定!$B$3:$B$1850,"<="&判定条件!$C$11,時間ごとの判定!$AQ$3:$AQ$1850,"利用可") -> 2 | K43: =IF(J43>=判定条件!$C$12,"利用可","不可") -> 不可 | L43: =COUNTIFS(時間ごとの判定!$A$3:$A$1850,$A43,時間ごとの判定!$B$3:$B$1850,">="&判定条件!$C$10,時間ごとの判定!$B$3:$B$1850,"<="&判定条件!$C$11,時間ごとの判定!$AT$3:$AT$1850,"利用可") -> 0 | M43: =IF(L43>=判定条件!$C$12,"利用可","不可") -> 不可 | N43: =COUNTIFS(時間ごとの判定!$A$3:$A$1850,$A43,時間ごとの判定!$B$3:$B$1850,">="&判定条件!$C$10,時間ごとの判定!$B$3:$B$1850,"<="&判定条件!$C$11,時間ごとの判定!$AW$3:$AW$1850,"利用可") -> 7 | O43: =IF(N43>=判定条件!$C$12,"利用可","不可") -> 利用可 | P43: =IF(AND(E43="利用可",G43="利用可",I43="利用可"),"利用可","不可") -> 不可 | Q43: =IF(AND(K43="利用可",M43="利用可",O43="利用可"),"利用可","不可") -> 不可 | R43: 3-2の排気・吸気温度が欠け（判定不能）
A44: 46273 | B44: 火 | C44: 平日 | D44: =COUNTIFS(時間ごとの判定!$A$3:$A$1850,$A44,時間ごとの判定!$B$3:$B$1850,">="&判定条件!$C$10,時間ごとの判定!$B$3:$B$1850,"<="&判定条件!$C$11,時間ごとの判定!$AH$3:$AH$1850,"利用可") -> 7 | E44: =IF(D44>=判定条件!$C$12,"利用可","不可") -> 利用可 | F44: =COUNTIFS(時間ごとの判定!$A$3:$A$1850,$A44,時間ごとの判定!$B$3:$B$1850,">="&判定条件!$C$10,時間ごとの判定!$B$3:$B$1850,"<="&判定条件!$C$11,時間ごとの判定!$AK$3:$AK$1850,"利用可") -> 9 | G44: =IF(F44>=判定条件!$C$12,"利用可","不可") -> 利用可 | H44: =COUNTIFS(時間ごとの判定!$A$3:$A$1850,$A44,時間ごとの判定!$B$3:$B$1850,">="&判定条件!$C$10,時間ごとの判定!$B$3:$B$1850,"<="&判定条件!$C$11,時間ごとの判定!$AN$3:$AN$1850,"利用可") -> 8 | I44: =IF(H44>=判定条件!$C$12,"利用可","不可") -> 利用可 | J44: =COUNTIFS(時間ごとの判定!$A$3:$A$1850,$A44,時間ごとの判定!$B$3:$B$1850,">="&判定条件!$C$10,時間ごとの判定!$B$3:$B$1850,"<="&判定条件!$C$11,時間ごとの判定!$AQ$3:$AQ$1850,"利用可") -> 8 | K44: =IF(J44>=判定条件!$C$12,"利用可","不可") -> 利用可 | L44: =COUNTIFS(時間ごとの判定!$A$3:$A$1850,$A44,時間ごとの判定!$B$3:$B$1850,">="&判定条件!$C$10,時間ごとの判定!$B$3:$B$1850,"<="&判定条件!$C$11,時間ごとの判定!$AT$3:$AT$1850,"利用可") -> 8 | M44: =IF(L44>=判定条件!$C$12,"利用可","不可") -> 利用可 | N44: =COUNTIFS(時間ごとの判定!$A$3:$A$1850,$A44,時間ごとの判定!$B$3:$B$1850,">="&判定条件!$C$10,時間ごとの判定!$B$3:$B$1850,"<="&判定条件!$C$11,時間ごとの判定!$AW$3:$AW$1850,"利用可") -> 9 | O44: =IF(N44>=判定条件!$C$12,"利用可","不可") -> 利用可 | P44: =IF(AND(E44="利用可",G44="利用可",I44="利用可"),"利用可","不可") -> 利用可 | Q44: =IF(AND(K44="利用可",M44="利用可",O44="利用可"),"利用可","不可") -> 利用可
...

Sheet 時間ごとの判定
A1: 日付 | B1: 時台 | C1: 曜日 | D1: 区分 | E1: 室外機 3-1 | H1: 室外機 3-2 | K1: 室外機 3-3 | N1: 室外機 8-1 | Q1: 室外機 8-2 | T1: 室外機 8-3 | W1: 室外機 11-1 | Z1: 室外機 11-2 | AC1: 室外機 11-3 | AF1: 組 8-1と3-1 | AI1: 組 8-2と3-2 | AL1: 組 8-3と3-3 | AO1: 組 11-1と3-1 | AR1: 組 11-2と3-2 | AU1: 組 11-3と3-3 | AX1: 列8（3区画とも利用可） | AY1: 列11（3区画とも利用可）
E2: 有効［分］ | F2: 運転中［分］ | G2: 判定 | H2: 有効［分］ | I2: 運転中［分］ | J2: 判定 | K2: 有効［分］ | L2: 運転中［分］ | M2: 判定 | N2: 有効［分］ | O2: 運転中［分］ | P2: 判定 | Q2: 有効［分］ | R2: 運転中［分］ | S2: 判定 | T2: 有効［分］ | U2: 運転中［分］ | V2: 判定 | W2: 有効［分］ | X2: 運転中［分］ | Y2: 判定 | Z2: 有効［分］ | AA2: 運転中［分］ | AB2: 判定 | AC2: 有効［分］ | AD2: 運転中［分］ | AE2: 判定 | AF2: 2台とも有効［分］ | AG2: 2台とも運転中［分］ | AH2: 判定 | AI2: 2台とも有効［分］ | AJ2: 2台とも運転中［分］ | AK2: 判定 | AL2: 2台とも有効［分］ | AM2: 2台とも運転中［分］ | AN2: 判定 | AO2: 2台とも有効［分］ | AP2: 2台とも運転中［分］ | AQ2: 判定 | AR2: 2台とも有効［分］ | AS2: 2台とも運転中［分］ | AT2: 判定 | AU2: 2台とも有効［分］ | AV2: 2台とも運転中［分］ | AW2: 判定
A3: 46232 | B3: 0 | C3: 水 | D3: 平日 | E3: 0 | F3: 0 | G3: =IF(E3<判定条件!$C$6,"判定不能",IF(F3>=判定条件!$C$7*E3,"運転",IF(F3<=判定条件!$C$8*E3,"停止","断続"))) -> 判定不能 | H3: 0 | I3: 0 | J3: =IF(H3<判定条件!$C$6,"判定不能",IF(I3>=判定条件!$C$7*H3,"運転",IF(I3<=判定条件!$C$8*H3,"停止","断続"))) -> 判定不能 | K3: 0 | L3: 0 | M3: =IF(K3<判定条件!$C$6,"判定不能",IF(L3>=判定条件!$C$7*K3,"運転",IF(L3<=判定条件!$C$8*K3,"停止","断続"))) -> 判定不能 | N3: 0 | O3: 0 | P3: =IF(N3<判定条件!$C$6,"判定不能",IF(O3>=判定条件!$C$7*N3,"運転",IF(O3<=判定条件!$C$8*N3,"停止","断続"))) -> 判定不能 | Q3: 0 | R3: 0 | S3: =IF(Q3<判定条件!$C$6,"判定不能",IF(R3>=判定条件!$C$7*Q3,"運転",IF(R3<=判定条件!$C$8*Q3,"停止","断続"))) -> 判定不能 | T3: 0 | U3: 0 | V3: =IF(T3<判定条件!$C$6,"判定不能",IF(U3>=判定条件!$C$7*T3,"運転",IF(U3<=判定条件!$C$8*T3,"停止","断続"))) -> 判定不能 | W3: 0 | X3: 0 | Y3: =IF(W3<判定条件!$C$6,"判定不能",IF(X3>=判定条件!$C$7*W3,"運転",IF(X3<=判定条件!$C$8*W3,"停止","断続"))) -> 判定不能 | Z3: 0 | AA3: 0 | AB3: =IF(Z3<判定条件!$C$6,"判定不能",IF(AA3>=判定条件!$C$7*Z3,"運転",IF(AA3<=判定条件!$C$8*Z3,"停止","断続"))) -> 判定不能 | AC3: 0 | AD3: 0 | AE3: =IF(AC3<判定条件!$C$6,"判定不能",IF(AD3>=判定条件!$C$7*AC3,"運転",IF(AD3<=判定条件!$C$8*AC3,"停止","断続"))) -> 判定不能 | AF3: 0 | AG3: 0 | AH3: =IF(OR(P3="判定不能",G3="判定不能"),"判定不能",IF(AG3>=判定条件!$C$9,"利用可",IF(AND(P3="停止",G3="停止"),"両方停止","運転がそろわない"))) -> 判定不能 | AI3: 0 | AJ3: 0 | AK3: =IF(OR(S3="判定不能",J3="判定不能"),"判定不能",IF(AJ3>=判定条件!$C$9,"利用可",IF(AND(S3="停止",J3="停止"),"両方停止","運転がそろわない"))) -> 判定不能 | AL3: 0 | AM3: 0 | AN3: =IF(OR(V3="判定不能",M3="判定不能"),"判定不能",IF(AM3>=判定条件!$C$9,"利用可",IF(AND(V3="停止",M3="停止"),"両方停止","運転がそろわない"))) -> 判定不能 | AO3: 0 | AP3: 0 | AQ3: =IF(OR(Y3="判定不能",G3="判定不能"),"判定不能",IF(AP3>=判定条件!$C$9,"利用可",IF(AND(Y3="停止",G3="停止"),"両方停止","運転がそろわない"))) -> 判定不能 | AR3: 0 | AS3: 0 | AT3: =IF(OR(AB3="判定不能",J3="判定不能"),"判定不能",IF(AS3>=判定条件!$C$9,"利用可",IF(AND(AB3="停止",J3="停止"),"両方停止","運転がそろわない"))) -> 判定不能 | AU3: 0 | AV3: 0 | AW3: =IF(OR(AE3="判定不能",M3="判定不能"),"判定不能",IF(AV3>=判定条件!$C$9,"利用可",IF(AND(AE3="停止",M3="停止"),"両方停止","運転がそろわない"))) -> 判定不能 | AX3: =IF(AND(AH3="利用可",AK3="利用可",AN3="利用可"),"利用可","不可") -> 不可 | AY3: =IF(AND(AQ3="利用可",AT3="利用可",AW3="利用可"),"利用可","不可") -> 不可
A4: 46232 | B4: 1 | C4: 水 | D4: 平日 | E4: 0 | F4: 0 | G4: =IF(E4<判定条件!$C$6,"判定不能",IF(F4>=判定条件!$C$7*E4,"運転",IF(F4<=判定条件!$C$8*E4,"停止","断続"))) -> 判定不能 | H4: 0 | I4: 0 | J4: =IF(H4<判定条件!$C$6,"判定不能",IF(I4>=判定条件!$C$7*H4,"運転",IF(I4<=判定条件!$C$8*H4,"停止","断続"))) -> 判定不能 | K4: 0 | L4: 0 | M4: =IF(K4<判定条件!$C$6,"判定不能",IF(L4>=判定条件!$C$7*K4,"運転",IF(L4<=判定条件!$C$8*K4,"停止","断続"))) -> 判定不能 | N4: 0 | O4: 0 | P4: =IF(N4<判定条件!$C$6,"判定不能",IF(O4>=判定条件!$C$7*N4,"運転",IF(O4<=判定条件!$C$8*N4,"停止","断続"))) -> 判定不能 | Q4: 0 | R4: 0 | S4: =IF(Q4<判定条件!$C$6,"判定不能",IF(R4>=判定条件!$C$7*Q4,"運転",IF(R4<=判定条件!$C$8*Q4,"停止","断続"))) -> 判定不能 | T4: 0 | U4: 0 | V4: =IF(T4<判定条件!$C$6,"判定不能",IF(U4>=判定条件!$C$7*T4,"運転",IF(U4<=判定条件!$C$8*T4,"停止","断続"))) -> 判定不能 | W4: 0 | X4: 0 | Y4: =IF(W4<判定条件!$C$6,"判定不能",IF(X4>=判定条件!$C$7*W4,"運転",IF(X4<=判定条件!$C$8*W4,"停止","断続"))) -> 判定不能 | Z4: 0 | AA4: 0 | AB4: =IF(Z4<判定条件!$C$6,"判定不能",IF(AA4>=判定条件!$C$7*Z4,"運転",IF(AA4<=判定条件!$C$8*Z4,"停止","断続"))) -> 判定不能 | AC4: 0 | AD4: 0 | AE4: =IF(AC4<判定条件!$C$6,"判定不能",IF(AD4>=判定条件!$C$7*AC4,"運転",IF(AD4<=判定条件!$C$8*AC4,"停止","断続"))) -> 判定不能 | AF4: 0 | AG4: 0 | AH4: =IF(OR(P4="判定不能",G4="判定不能"),"判定不能",IF(AG4>=判定条件!$C$9,"利用可",IF(AND(P4="停止",G4="停止"),"両方停止","運転がそろわない"))) -> 判定不能 | AI4: 0 | AJ4: 0 | AK4: =IF(OR(S4="判定不能",J4="判定不能"),"判定不能",IF(AJ4>=判定条件!$C$9,"利用可",IF(AND(S4="停止",J4="停止"),"両方停止","運転がそろわない"))) -> 判定不能 | AL4: 0 | AM4: 0 | AN4: =IF(OR(V4="判定不能",M4="判定不能"),"判定不能",IF(AM4>=判定条件!$C$9,"利用可",IF(AND(V4="停止",M4="停止"),"両方停止","運転がそろわない"))) -> 判定不能 | AO4: 0 | AP4: 0 | AQ4: =IF(OR(Y4="判定不能",G4="判定不能"),"判定不能",IF(AP4>=判定条件!$C$9,"利用可",IF(AND(Y4="停止",G4="停止"),"両方停止","運転がそろわない"))) -> 判定不能 | AR4: 0 | AS4: 0 | AT4: =IF(OR(AB4="判定不能",J4="判定不能"),"判定不能",IF(AS4>=判定条件!$C$9,"利用可",IF(AND(AB4="停止",J4="停止"),"両方停止","運転がそろわない"))) -> 判定不能 | AU4: 0 | AV4: 0 | AW4: =IF(OR(AE4="判定不能",M4="判定不能"),"判定不能",IF(AV4>=判定条件!$C$9,"利用可",IF(AND(AE4="停止",M4="停止"),"両方停止","運転がそろわない"))) -> 判定不能 | AX4: =IF(AND(AH4="利用可",AK4="利用可",AN4="利用可"),"利用可","不可") -> 不可 | AY4: =IF(AND(AQ4="利用可",AT4="利用可",AW4="利用可"),"利用可","不可") -> 不可
